Workbook

Sheet Info
A1: Region | B1: 5 | C1: Regional | D1: Name | E1: Maryk Haynes | H1: Steps for using this Excel scoring workbook correctly
C2: Director | D2: Email | E2: maryke.nau@gmail.co | G2: 1 | H2: (After copying 'WSMC Scoring' to your computer) Enter Region number in B1 on this sheet.
A3: Enter Knowdown Results | G3: 2 | H3: Enter Regional Director name and email in cells E1 and E2 on this sheet
A4: Place | B4: Name | E4: School | H4: (Don't forget to regularly save updates) For each school:
A5: 1 | B5: Andrew Lee | E5: Kamiak | G5: 3 | H5: You may change the tabs on the worksheets to school initials
A6: 2 | B6: JiYoon Hong | E6: Jackson | G6: 4 | H6: Enter ALL school Information in the pinkish boxes, omit HS or High School
A7: 3 | B7: Alex Reed | E7: Mariner | G7: 5 | H7: Enter Division (1 if 'AA', 'AAA', or 'AAAA' school, 2 if the school is smaller).
A8: Alternate | B8: Brandon Ng | E8: Mariner | G8: 6 | H8: Enter student names (first and last please ex: Kayla Kloss) in appropriate columns.
G9: 7 | H9: Enter the number of the Team Project team for each student on a Project Team
A10: Information | G10: 8 | H10: Enter the number of the Team Problem team for each student on a Prolem Team (note: JV teams must be numbered using numbers larger than the number in cell A9. A9 can be changed for each school. Watch for flags (pink box next to team score) on the varsity teams.)
A11: WSMC Contest Chair Person
A12: Jim Miller | G12: 9 | H12: Enter the number of the Team Topical team for each student on a Topical Team. Watch for flag for incorrect team composition. (Topical Individual are assumed for any student without a team number.)
A13: 201 Elk Haven Rd.
A14: Cle Elum 98922 | G14: 10 | H14: Enter 'x' in the Knowdown column by the name of each Knowdown contestent.
A15: 509-674-2317 | C15: Cell 509-674-8138 | G15: 11 | H15: Enter scores as soon as they are reported. They should be entered in their appropriate colums by their team numbers. (Project scores start in C4, Team Problem in C13, Topical Team Part One in F3, Topical Team Part Two in G3, Individual Topical Parts One and Two by the students' name.)
A16: millerionjim@gmail.com | D16: millerji@cwu.edu
G17: 12 | H17: (Don't forget to regularly save updates) At the end of the contest:
G18: 13 | H18: Enter the results of the Knowdown on this page. (Save)
A19: Never use the cut command (control x or command x)! | G19: 14 | H19: The results will be automatically calculated for each event. Click on the appropriate tabs to see the results. If you would like to print the results, select the protion of the worksheet you would like to print, select Print from the file menu, choose to print Selection.
D20: For the students playing up.. | G20: 15 | H20: How to deal with playing up: If a student is playing up as per the rules, Enter their name in the correct age/class group and In the Age/class group they are playing up in BUT in the group they are playing up in start their name with an x like Anna is a sophomore so enter Anna in the Sophomore list and then place xAnna in the the Seniors list if Anna is playing up as a Senior.

Sheet Proj
A1: =B1 | B1: =IF(E1="","",RANK(E1,$E$1:$E$100)) | C1: 1 | D1: 1 | E1: =IF(AHS!$C$4="","",AHS!$C$4) | F1: =CONCATENATE(IF(AHS!$J$13=$D1,CONCATENATE(AHS!$I$13,"-"),""),IF(AHS!$J$14=$D1,CONCATENATE(AHS!$I$14,"-"),""),IF(AHS!$J$15=$D1,CONCATENATE(AHS!$I$15,"-"),""),IF(AHS!$J$16=$D1,CONCATENATE(AHS!$I$16,"-"),""),IF(AHS!$J$17=$D1,CONCATENATE(AHS!$I$17,"-"),""),IF(AHS!$J$18=$D1,CONCATENATE(AHS!$I$18,"-"),""),IF(AHS!$J$19=$D1,CONCATENATE(AHS!$I$19,"-"),""),IF(AHS!$J$20=$D1,CONCATENATE(AHS!$I$20,"-"),""),IF(AHS!$J$21=$D1,CONCATENATE(AHS!$I$21,"-"),""),IF(AHS!$J$22=$D1,CONCATENATE(AHS!$I$22,"-"),""),) | G1: =CONCATENATE(IF(AHS!$J$23=$D1,CONCATENATE(AHS!$I$23,"-"),""),IF(AHS!$J$24=$D1,CONCATENATE(AHS!$I$24,"-"),""),IF(AHS!$J$25=$D1,CONCATENATE(AHS!$I$25,"-"),""),IF(AHS!$J$26=$D1,CONCATENATE(AHS!$I$26,"-"),""),IF(AHS!$J$27=$D1,CONCATENATE(AHS!$I$27,"-"),""),IF(AHS!$J$28=$D1,CONCATENATE(AHS!$I$28,"-"),""),IF(AHS!$J$29=$D1,CONCATENATE(AHS!$I$29,"-"),""),IF(AHS!$J$30=$D1,CONCATENATE(AHS!$I$30,"-"),""),IF(AHS!$J$31=$D1,CONCATENATE(AHS!$I$31,"-"),""),IF(AHS!$J$32=$D1,CONCATENATE(AHS!$I$32,"-"),"")) | H1: =CONCATENATE(IF(AHS!$R$13=$D1,CONCATENATE(AHS!$Q$13,"-"),""),IF(AHS!$R$14=$D1,CONCATENATE(AHS!$Q$14,"-"),""),IF(AHS!$R$15=$D1,CONCATENATE(AHS!$Q$15,"-"),""),IF(AHS!$R$16=$D1,CONCATENATE(AHS!$Q$16,"-"),""),IF(AHS!$R$17=$D1,CONCATENATE(AHS!$Q$17,"-"),""),IF(AHS!$R$18=$D1,CONCATENATE(AHS!$Q$18,"-"),""),IF(AHS!$R$19=$D1,CONCATENATE(AHS!$Q$19,"-"),""),IF(AHS!$R$20=$D1,CONCATENATE(AHS!$Q$20,"-"),""),IF(AHS!$R$21=$D1,CONCATENATE(AHS!$Q$21,"-"),""),IF(AHS!$R$22=$D1,CONCATENATE(AHS!$Q$22,"-"),"")) | I1: =CONCATENATE(,IF(AHS!$R$23=$D1,CONCATENATE(AHS!$Q$23,"-"),""),IF(AHS!$R$24=$D1,CONCATENATE(AHS!$Q$24,"-"),""),IF(AHS!$R$25=$D1,CONCATENATE(AHS!$Q$25,"-"),""),IF(AHS!$R$26=$D1,CONCATENATE(AHS!$Q$26,"-"),""),IF(AHS!$R$27=$D1,CONCATENATE(AHS!$Q$27,"-"),""),IF(AHS!$R$28=$D1,CONCATENATE(AHS!$Q$28,"-"),""),IF(AHS!$R$29=$D1,CONCATENATE(AHS!$Q$29,"-"),""),IF(AHS!$R$30=$D1,CONCATENATE(AHS!$Q$30,"-"),""),IF(AHS!$R$31=$D1,CONCATENATE(AHS!$Q$31,"-"),""),IF(AHS!$R$32=$D1,CONCATENATE(AHS!$Q$32,"-"),"")) | J1: =CONCATENATE(IF(AHS!$Z$13=$D1,CONCATENATE(AHS!$Y$13,"-"),""),IF(AHS!$Z$14=$D1,CONCATENATE(AHS!$Y$14,"-"),""),IF(AHS!$Z$15=$D1,CONCATENATE(AHS!$Y$15,"-"),""),IF(AHS!$Z$16=$D1,CONCATENATE(AHS!$Y$16,"-"),""),IF(AHS!$Z$17=$D1,CONCATENATE(AHS!$Y$17,"-"),""),IF(AHS!$Z$18=$D1,CONCATENATE(AHS!$Y$18,"-"),""),IF(AHS!$Z$19=$D1,CONCATENATE(AHS!$Y$19,"-"),""),IF(AHS!$Z$20=$D1,CONCATENATE(AHS!$Y$20,"-"),""),IF(AHS!$Z$21=$D1,CONCATENATE(AHS!$Y$21,"-"),""),IF(AHS!$Z$22=$D1,CONCATENATE(AHS!$Y$22,"-"),""),"") | K1: =CONCATENATE(IF(AHS!$Z$23=$D1,CONCATENATE(AHS!$Y$23,"-"),""),IF(AHS!$Z$24=$D1,CONCATENATE(AHS!$Y$24,"-"),""),IF(AHS!$Z$25=$D1,CONCATENATE(AHS!$Y$25,"-"),""),IF(AHS!$Z$26=$D1,CONCATENATE(AHS!$Y$26,"-"),""),IF(AHS!$Z$27=$D1,CONCATENATE(AHS!$Y$27,"-"),""),IF(AHS!$Z$28=$D1,CONCATENATE(AHS!$Y$28,"-"),""),IF(AHS!$Z$29=$D1,CONCATENATE(AHS!$Y$29,"-"),""),IF(AHS!$Z$30=$D1,CONCATENATE(AHS!$Y$30,"-"),""),IF(AHS!$Z$31=$D1,CONCATENATE(AHS!$Y$31,"-"),""),IF(AHS!$Z$32=$D1,CONCATENATE(AHS!$Y$32,"-"),"")) | L1: =CONCATENATE(IF(AHS!$AH$13=$D1,CONCATENATE(AHS!$AG$13,"-"),""),IF(AHS!$AH$14=$D1,CONCATENATE(AHS!$AG$14,"-"),""),IF(AHS!$AH$15=$D1,CONCATENATE(AHS!$AG$15,"-"),""),IF(AHS!$AH$16=$D1,CONCATENATE(AHS!$AG$16,"-"),""),IF(AHS!$AH$17=$D1,CONCATENATE(AHS!$AG$17,"-"),""),IF(AHS!$AH$18=$D1,CONCATENATE(AHS!$AG$18,"-"),""),IF(AHS!$AH$19=$D1,CONCATENATE(AHS!$AG$19,"-"),""),IF(AHS!$AH$20=$D1,CONCATENATE(AHS!$AG$20,"-"),""),IF(AHS!$AH$21=$D1,CONCATENATE(AHS!$AG$21,"-"),""),IF(AHS!$AH$22=$D1,CONCATENATE(AHS!$AG$22,"-"),""),"") | M1: =CONCATENATE(IF(AHS!$AH$23=$D1,CONCATENATE(AHS!$AG$23,"-"),""),IF(AHS!$AH$24=$D1,CONCATENATE(AHS!$AG$24,"-"),""),IF(AHS!$AH$25=$D1,CONCATENATE(AHS!$AG$25,"-"),""),IF(AHS!$AH$26=$D1,CONCATENATE(AHS!$AG$26,"-"),""),IF(AHS!$AH$27=$D1,CONCATENATE(AHS!$AG$27,"-"),""),IF(AHS!$AH$28=$D1,CONCATENATE(AHS!$AG$28,"-"),""),IF(AHS!$AH$29=$D1,CONCATENATE(AHS!$AG$29,"-"),""),IF(AHS!$AH$30=$D1,CONCATENATE(AHS!$AG$30,"-"),""),IF(AHS!$AH$31=$D1,CONCATENATE(AHS!$AG$31,"-"),""),IF(AHS!$AH$32=$D1,CONCATENATE(AHS!$AG$32,"-"),"")) | N1: =CONCATENATE(F1,G1,H1,I1,J1,K1,L1,M1) | P1: Team Projects Results
A2: =IF(B2="","",COUNTIF($B$1:B1,B2)+B2) | B2: =IF(E2="","",RANK(E2,$E$1:$E$100)) | C2: 1 | D2: 2 | E2: =IF(AHS!$C$5="","",AHS!$C$5) | F2: =CONCATENATE(IF(AHS!$J$13=$D2,CONCATENATE(AHS!$I$13,"-"),""),IF(AHS!$J$14=$D2,CONCATENATE(AHS!$I$14,"-"),""),IF(AHS!$J$15=$D2,CONCATENATE(AHS!$I$15,"-"),""),IF(AHS!$J$16=$D2,CONCATENATE(AHS!$I$16,"-"),""),IF(AHS!$J$17=$D2,CONCATENATE(AHS!$I$17,"-"),""),IF(AHS!$J$18=$D2,CONCATENATE(AHS!$I$18,"-"),""),IF(AHS!$J$19=$D2,CONCATENATE(AHS!$I$19,"-"),""),IF(AHS!$J$20=$D2,CONCATENATE(AHS!$I$20,"-"),""),IF(AHS!$J$21=$D2,CONCATENATE(AHS!$I$21,"-"),""),IF(AHS!$J$22=$D2,CONCATENATE(AHS!$I$22,"-"),""),) | G2: =CONCATENATE(IF(AHS!$J$23=$D2,CONCATENATE(AHS!$I$23,"-"),""),IF(AHS!$J$24=$D2,CONCATENATE(AHS!$I$24,"-"),""),IF(AHS!$J$25=$D2,CONCATENATE(AHS!$I$25,"-"),""),IF(AHS!$J$26=$D2,CONCATENATE(AHS!$I$26,"-"),""),IF(AHS!$J$27=$D2,CONCATENATE(AHS!$I$27,"-"),""),IF(AHS!$J$28=$D2,CONCATENATE(AHS!$I$28,"-"),""),IF(AHS!$J$29=$D2,CONCATENATE(AHS!$I$29,"-"),""),IF(AHS!$J$30=$D2,CONCATENATE(AHS!$I$30,"-"),""),IF(AHS!$J$31=$D2,CONCATENATE(AHS!$I$31,"-"),""),IF(AHS!$J$32=$D2,CONCATENATE(AHS!$I$32,"-"),"")) | H2: =CONCATENATE(IF(AHS!$R$13=$D2,CONCATENATE(AHS!$Q$13,"-"),""),IF(AHS!$R$14=$D2,CONCATENATE(AHS!$Q$14,"-"),""),IF(AHS!$R$15=$D2,CONCATENATE(AHS!$Q$15,"-"),""),IF(AHS!$R$16=$D2,CONCATENATE(AHS!$Q$16,"-"),""),IF(AHS!$R$17=$D2,CONCATENATE(AHS!$Q$17,"-"),""),IF(AHS!$R$18=$D2,CONCATENATE(AHS!$Q$18,"-"),""),IF(AHS!$R$19=$D2,CONCATENATE(AHS!$Q$19,"-"),""),IF(AHS!$R$20=$D2,CONCATENATE(AHS!$Q$20,"-"),""),IF(AHS!$R$21=$D2,CONCATENATE(AHS!$Q$21,"-"),""),IF(AHS!$R$22=$D2,CONCATENATE(AHS!$Q$22,"-"),"")) | I2: =CONCATENATE(,IF(AHS!$R$23=$D2,CONCATENATE(AHS!$Q$23,"-"),""),IF(AHS!$R$24=$D2,CONCATENATE(AHS!$Q$24,"-"),""),IF(AHS!$R$25=$D2,CONCATENATE(AHS!$Q$25,"-"),""),IF(AHS!$R$26=$D2,CONCATENATE(AHS!$Q$26,"-"),""),IF(AHS!$R$27=$D2,CONCATENATE(AHS!$Q$27,"-"),""),IF(AHS!$R$28=$D2,CONCATENATE(AHS!$Q$28,"-"),""),IF(AHS!$R$29=$D2,CONCATENATE(AHS!$Q$29,"-"),""),IF(AHS!$R$30=$D2,CONCATENATE(AHS!$Q$30,"-"),""),IF(AHS!$R$31=$D2,CONCATENATE(AHS!$Q$31,"-"),""),IF(AHS!$R$32=$D2,CONCATENATE(AHS!$Q$32,"-"),"")) | J2: =CONCATENATE(IF(AHS!$Z$13=$D2,CONCATENATE(AHS!$Y$13,"-"),""),IF(AHS!$Z$14=$D2,CONCATENATE(AHS!$Y$14,"-"),""),IF(AHS!$Z$15=$D2,CONCATENATE(AHS!$Y$15,"-"),""),IF(AHS!$Z$16=$D2,CONCATENATE(AHS!$Y$16,"-"),""),IF(AHS!$Z$17=$D2,CONCATENATE(AHS!$Y$17,"-"),""),IF(AHS!$Z$18=$D2,CONCATENATE(AHS!$Y$18,"-"),""),IF(AHS!$Z$19=$D2,CONCATENATE(AHS!$Y$19,"-"),""),IF(AHS!$Z$20=$D2,CONCATENATE(AHS!$Y$20,"-"),""),IF(AHS!$Z$21=$D2,CONCATENATE(AHS!$Y$21,"-"),""),IF(AHS!$Z$22=$D2,CONCATENATE(AHS!$Y$22,"-"),""),"") | K2: =CONCATENATE(IF(AHS!$Z$23=$D2,CONCATENATE(AHS!$Y$23,"-"),""),IF(AHS!$Z$24=$D2,CONCATENATE(AHS!$Y$24,"-"),""),IF(AHS!$Z$25=$D2,CONCATENATE(AHS!$Y$25,"-"),""),IF(AHS!$Z$26=$D2,CONCATENATE(AHS!$Y$26,"-"),""),IF(AHS!$Z$27=$D2,CONCATENATE(AHS!$Y$27,"-"),""),IF(AHS!$Z$28=$D2,CONCATENATE(AHS!$Y$28,"-"),""),IF(AHS!$Z$29=$D2,CONCATENATE(AHS!$Y$29,"-"),""),IF(AHS!$Z$30=$D2,CONCATENATE(AHS!$Y$30,"-"),""),IF(AHS!$Z$31=$D2,CONCATENATE(AHS!$Y$31,"-"),""),IF(AHS!$Z$32=$D2,CONCATENATE(AHS!$Y$32,"-"),"")) | L2: =CONCATENATE(IF(AHS!$AH$13=$D2,CONCATENATE(AHS!$AG$13,"-"),""),IF(AHS!$AH$14=$D2,CONCATENATE(AHS!$AG$14,"-"),""),IF(AHS!$AH$15=$D2,CONCATENATE(AHS!$AG$15,"-"),""),IF(AHS!$AH$16=$D2,CONCATENATE(AHS!$AG$16,"-"),""),IF(AHS!$AH$17=$D2,CONCATENATE(AHS!$AG$17,"-"),""),IF(AHS!$AH$18=$D2,CONCATENATE(AHS!$AG$18,"-"),""),IF(AHS!$AH$19=$D2,CONCATENATE(AHS!$AG$19,"-"),""),IF(AHS!$AH$20=$D2,CONCATENATE(AHS!$AG$20,"-"),""),IF(AHS!$AH$21=$D2,CONCATENATE(AHS!$AG$21,"-"),""),IF(AHS!$AH$22=$D2,CONCATENATE(AHS!$AG$22,"-"),""),"") | M2: =CONCATENATE(IF(AHS!$AH$23=$D2,CONCATENATE(AHS!$AG$23,"-"),""),IF(AHS!$AH$24=$D2,CONCATENATE(AHS!$AG$24,"-"),""),IF(AHS!$AH$25=$D2,CONCATENATE(AHS!$AG$25,"-"),""),IF(AHS!$AH$26=$D2,CONCATENATE(AHS!$AG$26,"-"),""),IF(AHS!$AH$27=$D2,CONCATENATE(AHS!$AG$27,"-"),""),IF(AHS!$AH$28=$D2,CONCATENATE(AHS!$AG$28,"-"),""),IF(AHS!$AH$29=$D2,CONCATENATE(AHS!$AG$29,"-"),""),IF(AHS!$AH$30=$D2,CONCATENATE(AHS!$AG$30,"-"),""),IF(AHS!$AH$31=$D2,CONCATENATE(AHS!$AG$31,"-"),""),IF(AHS!$AH$32=$D2,CONCATENATE(AHS!$AG$32,"-"),"")) | N2: =CONCATENATE(F2,G2,H2,I2,J2,K2,L2,M2) | P2: Place | Q2: Score | R2: School | S2: Team | T2: Names
A3: =IF(B3="","",COUNTIF($B$1:B2,B3)+B3) | B3: =IF(E3="","",RANK(E3,$E$1:$E$100)) | C3: 1 | D3: 3 | E3: =IF(AHS!$C$6="","",AHS!$C$6) | F3: =CONCATENATE(IF(AHS!$J$13=$D3,CONCATENATE(AHS!$I$13,"-"),""),IF(AHS!$J$14=$D3,CONCATENATE(AHS!$I$14,"-"),""),IF(AHS!$J$15=$D3,CONCATENATE(AHS!$I$15,"-"),""),IF(AHS!$J$16=$D3,CONCATENATE(AHS!$I$16,"-"),""),IF(AHS!$J$17=$D3,CONCATENATE(AHS!$I$17,"-"),""),IF(AHS!$J$18=$D3,CONCATENATE(AHS!$I$18,"-"),""),IF(AHS!$J$19=$D3,CONCATENATE(AHS!$I$19,"-"),""),IF(AHS!$J$20=$D3,CONCATENATE(AHS!$I$20,"-"),""),IF(AHS!$J$21=$D3,CONCATENATE(AHS!$I$21,"-"),""),IF(AHS!$J$22=$D3,CONCATENATE(AHS!$I$22,"-"),""),) | G3: =CONCATENATE(IF(AHS!$J$23=$D3,CONCATENATE(AHS!$I$23,"-"),""),IF(AHS!$J$24=$D3,CONCATENATE(AHS!$I$24,"-"),""),IF(AHS!$J$25=$D3,CONCATENATE(AHS!$I$25,"-"),""),IF(AHS!$J$26=$D3,CONCATENATE(AHS!$I$26,"-"),""),IF(AHS!$J$27=$D3,CONCATENATE(AHS!$I$27,"-"),""),IF(AHS!$J$28=$D3,CONCATENATE(AHS!$I$28,"-"),""),IF(AHS!$J$29=$D3,CONCATENATE(AHS!$I$29,"-"),""),IF(AHS!$J$30=$D3,CONCATENATE(AHS!$I$30,"-"),""),IF(AHS!$J$31=$D3,CONCATENATE(AHS!$I$31,"-"),""),IF(AHS!$J$32=$D3,CONCATENATE(AHS!$I$32,"-"),"")) | H3: =CONCATENATE(IF(AHS!$R$13=$D3,CONCATENATE(AHS!$Q$13,"-"),""),IF(AHS!$R$14=$D3,CONCATENATE(AHS!$Q$14,"-"),""),IF(AHS!$R$15=$D3,CONCATENATE(AHS!$Q$15,"-"),""),IF(AHS!$R$16=$D3,CONCATENATE(AHS!$Q$16,"-"),""),IF(AHS!$R$17=$D3,CONCATENATE(AHS!$Q$17,"-"),""),IF(AHS!$R$18=$D3,CONCATENATE(AHS!$Q$18,"-"),""),IF(AHS!$R$19=$D3,CONCATENATE(AHS!$Q$19,"-"),""),IF(AHS!$R$20=$D3,CONCATENATE(AHS!$Q$20,"-"),""),IF(AHS!$R$21=$D3,CONCATENATE(AHS!$Q$21,"-"),""),IF(AHS!$R$22=$D3,CONCATENATE(AHS!$Q$22,"-"),"")) | I3: =CONCATENATE(,IF(AHS!$R$23=$D3,CONCATENATE(AHS!$Q$23,"-"),""),IF(AHS!$R$24=$D3,CONCATENATE(AHS!$Q$24,"-"),""),IF(AHS!$R$25=$D3,CONCATENATE(AHS!$Q$25,"-"),""),IF(AHS!$R$26=$D3,CONCATENATE(AHS!$Q$26,"-"),""),IF(AHS!$R$27=$D3,CONCATENATE(AHS!$Q$27,"-"),""),IF(AHS!$R$28=$D3,CONCATENATE(AHS!$Q$28,"-"),""),IF(AHS!$R$29=$D3,CONCATENATE(AHS!$Q$29,"-"),""),IF(AHS!$R$30=$D3,CONCATENATE(AHS!$Q$30,"-"),""),IF(AHS!$R$31=$D3,CONCATENATE(AHS!$Q$31,"-"),""),IF(AHS!$R$32=$D3,CONCATENATE(AHS!$Q$32,"-"),"")) | J3: =CONCATENATE(IF(AHS!$Z$13=$D3,CONCATENATE(AHS!$Y$13,"-"),""),IF(AHS!$Z$14=$D3,CONCATENATE(AHS!$Y$14,"-"),""),IF(AHS!$Z$15=$D3,CONCATENATE(AHS!$Y$15,"-"),""),IF(AHS!$Z$16=$D3,CONCATENATE(AHS!$Y$16,"-"),""),IF(AHS!$Z$17=$D3,CONCATENATE(AHS!$Y$17,"-"),""),IF(AHS!$Z$18=$D3,CONCATENATE(AHS!$Y$18,"-"),""),IF(AHS!$Z$19=$D3,CONCATENATE(AHS!$Y$19,"-"),""),IF(AHS!$Z$20=$D3,CONCATENATE(AHS!$Y$20,"-"),""),IF(AHS!$Z$21=$D3,CONCATENATE(AHS!$Y$21,"-"),""),IF(AHS!$Z$22=$D3,CONCATENATE(AHS!$Y$22,"-"),""),"") | K3: =CONCATENATE(IF(AHS!$Z$23=$D3,CONCATENATE(AHS!$Y$23,"-"),""),IF(AHS!$Z$24=$D3,CONCATENATE(AHS!$Y$24,"-"),""),IF(AHS!$Z$25=$D3,CONCATENATE(AHS!$Y$25,"-"),""),IF(AHS!$Z$26=$D3,CONCATENATE(AHS!$Y$26,"-"),""),IF(AHS!$Z$27=$D3,CONCATENATE(AHS!$Y$27,"-"),""),IF(AHS!$Z$28=$D3,CONCATENATE(AHS!$Y$28,"-"),""),IF(AHS!$Z$29=$D3,CONCATENATE(AHS!$Y$29,"-"),""),IF(AHS!$Z$30=$D3,CONCATENATE(AHS!$Y$30,"-"),""),IF(AHS!$Z$31=$D3,CONCATENATE(AHS!$Y$31,"-"),""),IF(AHS!$Z$32=$D3,CONCATENATE(AHS!$Y$32,"-"),"")) | L3: =CONCATENATE(IF(AHS!$AH$13=$D3,CONCATENATE(AHS!$AG$13,"-"),""),IF(AHS!$AH$14=$D3,CONCATENATE(AHS!$AG$14,"-"),""),IF(AHS!$AH$15=$D3,CONCATENATE(AHS!$AG$15,"-"),""),IF(AHS!$AH$16=$D3,CONCATENATE(AHS!$AG$16,"-"),""),IF(AHS!$AH$17=$D3,CONCATENATE(AHS!$AG$17,"-"),""),IF(AHS!$AH$18=$D3,CONCATENATE(AHS!$AG$18,"-"),""),IF(AHS!$AH$19=$D3,CONCATENATE(AHS!$AG$19,"-"),""),IF(AHS!$AH$20=$D3,CONCATENATE(AHS!$AG$20,"-"),""),IF(AHS!$AH$21=$D3,CONCATENATE(AHS!$AG$21,"-"),""),IF(AHS!$AH$22=$D3,CONCATENATE(AHS!$AG$22,"-"),""),"") | M3: =CONCATENATE(IF(AHS!$AH$23=$D3,CONCATENATE(AHS!$AG$23,"-"),""),IF(AHS!$AH$24=$D3,CONCATENATE(AHS!$AG$24,"-"),""),IF(AHS!$AH$25=$D3,CONCATENATE(AHS!$AG$25,"-"),""),IF(AHS!$AH$26=$D3,CONCATENATE(AHS!$AG$26,"-"),""),IF(AHS!$AH$27=$D3,CONCATENATE(AHS!$AG$27,"-"),""),IF(AHS!$AH$28=$D3,CONCATENATE(AHS!$AG$28,"-"),""),IF(AHS!$AH$29=$D3,CONCATENATE(AHS!$AG$29,"-"),""),IF(AHS!$AH$30=$D3,CONCATENATE(AHS!$AG$30,"-"),""),IF(AHS!$AH$31=$D3,CONCATENATE(AHS!$AG$31,"-"),""),IF(AHS!$AH$32=$D3,CONCATENATE(AHS!$AG$32,"-"),"")) | N3: =CONCATENATE(F3,G3,H3,I3,J3,K3,L3,M3) | O3: 1 | P3: =IF(ISERROR(VLOOKUP($O3,$A$1:$B$100,2,FALSE)),"",VLOOKUP($O3,$A$1:$B$100,2,FALSE)) -> 1 | Q3: =IF(P3="","",VLOOKUP($O3,$A$1:$E$100,5,FALSE)) -> 53.5 | R3: =IF(P3="","",CHOOSE(VLOOKUP($O3,$A$1:$C$100,3,FALSE),AHS!$M$1,BHS!$M$1,CHS!$M$1,HMJHS!$M$1,KHS!$M$1,Kings!$M$1,MHS!$M$1,SWHS!$M$1,AMHS!$M$1,'S10'!$M$1,'S11'!$M$1,'S12'!$M$1,'S13'!$M$1,'S14'!$M$1,'S15'!$M$1,'S16'!$M$1,'S17'!$M$1,'S18'!$M$1,'S19'!$M$1,'S20'!$M$1)) -> Cascade High School | S3: =IF(P3="","",VLOOKUP($O3,$A$1:$E$100,4,FALSE)) -> 1 | T3: =IF(P3="","",VLOOKUP($O3,$A$1:$N$100,14,FALSE)) -> Jacob Hopkins-Nathan Kim-
A4: =IF(B4="","",COUNTIF($B$1:B3,B4)+B4) | B4: =IF(E4="","",RANK(E4,$E$1:$E$100)) | C4: 1 | D4: 4 | E4: =IF(AHS!$C$7="","",AHS!$C$7) | F4: =CONCATENATE(IF(AHS!$J$13=$D4,CONCATENATE(AHS!$I$13,"-"),""),IF(AHS!$J$14=$D4,CONCATENATE(AHS!$I$14,"-"),""),IF(AHS!$J$15=$D4,CONCATENATE(AHS!$I$15,"-"),""),IF(AHS!$J$16=$D4,CONCATENATE(AHS!$I$16,"-"),""),IF(AHS!$J$17=$D4,CONCATENATE(AHS!$I$17,"-"),""),IF(AHS!$J$18=$D4,CONCATENATE(AHS!$I$18,"-"),""),IF(AHS!$J$19=$D4,CONCATENATE(AHS!$I$19,"-"),""),IF(AHS!$J$20=$D4,CONCATENATE(AHS!$I$20,"-"),""),IF(AHS!$J$21=$D4,CONCATENATE(AHS!$I$21,"-"),""),IF(AHS!$J$22=$D4,CONCATENATE(AHS!$I$22,"-"),""),) | G4: =CONCATENATE(IF(AHS!$J$23=$D4,CONCATENATE(AHS!$I$23,"-"),""),IF(AHS!$J$24=$D4,CONCATENATE(AHS!$I$24,"-"),""),IF(AHS!$J$25=$D4,CONCATENATE(AHS!$I$25,"-"),""),IF(AHS!$J$26=$D4,CONCATENATE(AHS!$I$26,"-"),""),IF(AHS!$J$27=$D4,CONCATENATE(AHS!$I$27,"-"),""),IF(AHS!$J$28=$D4,CONCATENATE(AHS!$I$28,"-"),""),IF(AHS!$J$29=$D4,CONCATENATE(AHS!$I$29,"-"),""),IF(AHS!$J$30=$D4,CONCATENATE(AHS!$I$30,"-"),""),IF(AHS!$J$31=$D4,CONCATENATE(AHS!$I$31,"-"),""),IF(AHS!$J$32=$D4,CONCATENATE(AHS!$I$32,"-"),"")) | H4: =CONCATENATE(IF(AHS!$R$13=$D4,CONCATENATE(AHS!$Q$13,"-"),""),IF(AHS!$R$14=$D4,CONCATENATE(AHS!$Q$14,"-"),""),IF(AHS!$R$15=$D4,CONCATENATE(AHS!$Q$15,"-"),""),IF(AHS!$R$16=$D4,CONCATENATE(AHS!$Q$16,"-"),""),IF(AHS!$R$17=$D4,CONCATENATE(AHS!$Q$17,"-"),""),IF(AHS!$R$18=$D4,CONCATENATE(AHS!$Q$18,"-"),""),IF(AHS!$R$19=$D4,CONCATENATE(AHS!$Q$19,"-"),""),IF(AHS!$R$20=$D4,CONCATENATE(AHS!$Q$20,"-"),""),IF(AHS!$R$21=$D4,CONCATENATE(AHS!$Q$21,"-"),""),IF(AHS!$R$22=$D4,CONCATENATE(AHS!$Q$22,"-"),"")) | I4: =CONCATENATE(,IF(AHS!$R$23=$D4,CONCATENATE(AHS!$Q$23,"-"),""),IF(AHS!$R$24=$D4,CONCATENATE(AHS!$Q$24,"-"),""),IF(AHS!$R$25=$D4,CONCATENATE(AHS!$Q$25,"-"),""),IF(AHS!$R$26=$D4,CONCATENATE(AHS!$Q$26,"-"),""),IF(AHS!$R$27=$D4,CONCATENATE(AHS!$Q$27,"-"),""),IF(AHS!$R$28=$D4,CONCATENATE(AHS!$Q$28,"-"),""),IF(AHS!$R$29=$D4,CONCATENATE(AHS!$Q$29,"-"),""),IF(AHS!$R$30=$D4,CONCATENATE(AHS!$Q$30,"-"),""),IF(AHS!$R$31=$D4,CONCATENATE(AHS!$Q$31,"-"),""),IF(AHS!$R$32=$D4,CONCATENATE(AHS!$Q$32,"-"),"")) | J4: =CONCATENATE(IF(AHS!$Z$13=$D4,CONCATENATE(AHS!$Y$13,"-"),""),IF(AHS!$Z$14=$D4,CONCATENATE(AHS!$Y$14,"-"),""),IF(AHS!$Z$15=$D4,CONCATENATE(AHS!$Y$15,"-"),""),IF(AHS!$Z$16=$D4,CONCATENATE(AHS!$Y$16,"-"),""),IF(AHS!$Z$17=$D4,CONCATENATE(AHS!$Y$17,"-"),""),IF(AHS!$Z$18=$D4,CONCATENATE(AHS!$Y$18,"-"),""),IF(AHS!$Z$19=$D4,CONCATENATE(AHS!$Y$19,"-"),""),IF(AHS!$Z$20=$D4,CONCATENATE(AHS!$Y$20,"-"),""),IF(AHS!$Z$21=$D4,CONCATENATE(AHS!$Y$21,"-"),""),IF(AHS!$Z$22=$D4,CONCATENATE(AHS!$Y$22,"-"),""),"") | K4: =CONCATENATE(IF(AHS!$Z$23=$D4,CONCATENATE(AHS!$Y$23,"-"),""),IF(AHS!$Z$24=$D4,CONCATENATE(AHS!$Y$24,"-"),""),IF(AHS!$Z$25=$D4,CONCATENATE(AHS!$Y$25,"-"),""),IF(AHS!$Z$26=$D4,CONCATENATE(AHS!$Y$26,"-"),""),IF(AHS!$Z$27=$D4,CONCATENATE(AHS!$Y$27,"-"),""),IF(AHS!$Z$28=$D4,CONCATENATE(AHS!$Y$28,"-"),""),IF(AHS!$Z$29=$D4,CONCATENATE(AHS!$Y$29,"-"),""),IF(AHS!$Z$30=$D4,CONCATENATE(AHS!$Y$30,"-"),""),IF(AHS!$Z$31=$D4,CONCATENATE(AHS!$Y$31,"-"),""),IF(AHS!$Z$32=$D4,CONCATENATE(AHS!$Y$32,"-"),"")) | L4: =CONCATENATE(IF(AHS!$AH$13=$D4,CONCATENATE(AHS!$AG$13,"-"),""),IF(AHS!$AH$14=$D4,CONCATENATE(AHS!$AG$14,"-"),""),IF(AHS!$AH$15=$D4,CONCATENATE(AHS!$AG$15,"-"),""),IF(AHS!$AH$16=$D4,CONCATENATE(AHS!$AG$16,"-"),""),IF(AHS!$AH$17=$D4,CONCATENATE(AHS!$AG$17,"-"),""),IF(AHS!$AH$18=$D4,CONCATENATE(AHS!$AG$18,"-"),""),IF(AHS!$AH$19=$D4,CONCATENATE(AHS!$AG$19,"-"),""),IF(AHS!$AH$20=$D4,CONCATENATE(AHS!$AG$20,"-"),""),IF(AHS!$AH$21=$D4,CONCATENATE(AHS!$AG$21,"-"),""),IF(AHS!$AH$22=$D4,CONCATENATE(AHS!$AG$22,"-"),""),"") | M4: =CONCATENATE(IF(AHS!$AH$23=$D4,CONCATENATE(AHS!$AG$23,"-"),""),IF(AHS!$AH$24=$D4,CONCATENATE(AHS!$AG$24,"-"),""),IF(AHS!$AH$25=$D4,CONCATENATE(AHS!$AG$25,"-"),""),IF(AHS!$AH$26=$D4,CONCATENATE(AHS!$AG$26,"-"),""),IF(AHS!$AH$27=$D4,CONCATENATE(AHS!$AG$27,"-"),""),IF(AHS!$AH$28=$D4,CONCATENATE(AHS!$AG$28,"-"),""),IF(AHS!$AH$29=$D4,CONCATENATE(AHS!$AG$29,"-"),""),IF(AHS!$AH$30=$D4,CONCATENATE(AHS!$AG$30,"-"),""),IF(AHS!$AH$31=$D4,CONCATENATE(AHS!$AG$31,"-"),""),IF(AHS!$AH$32=$D4,CONCATENATE(AHS!$AG$32,"-"),"")) | N4: =CONCATENATE(F4,G4,H4,I4,J4,K4,L4,M4) | O4: 2 | P4: =IF(ISERROR(VLOOKUP($O4,$A$1:$B$100,2,FALSE)),"",VLOOKUP($O4,$A$1:$B$100,2,FALSE)) -> 2 | Q4: =IF(P4="","",VLOOKUP($O4,$A$1:$E$100,5,FALSE)) -> 50.5 | R4: =IF(P4="","",CHOOSE(VLOOKUP($O4,$A$1:$C$100,3,FALSE),AHS!$M$1,BHS!$M$1,CHS!$M$1,HMJHS!$M$1,KHS!$M$1,Kings!$M$1,MHS!$M$1,SWHS!$M$1,AMHS!$M$1,'S10'!$M$1,'S11'!$M$1,'S12'!$M$1,'S13'!$M$1,'S14'!$M$1,'S15'!$M$1,'S16'!$M$1,'S17'!$M$1,'S18'!$M$1,'S19'!$M$1,'S20'!$M$1)) -> King's High School | S4: =IF(P4="","",VLOOKUP($O4,$A$1:$E$100,4,FALSE)) -> 1 | T4: =IF(P4="","",VLOOKUP($O4,$A$1:$N$100,14,FALSE)) -> Sophia Liao-Chloe Byun-
A5: =IF(B5="","",COUNTIF($B$1:B4,B5)+B5) | B5: =IF(E5="","",RANK(E5,$E$1:$E$100)) | C5: 1 | D5: 5 | E5: =IF(AHS!$C$8="","",AHS!$C$8) | F5: =CONCATENATE(IF(AHS!$J$13=$D5,CONCATENATE(AHS!$I$13,"-"),""),IF(AHS!$J$14=$D5,CONCATENATE(AHS!$I$14,"-"),""),IF(AHS!$J$15=$D5,CONCATENATE(AHS!$I$15,"-"),""),IF(AHS!$J$16=$D5,CONCATENATE(AHS!$I$16,"-"),""),IF(AHS!$J$17=$D5,CONCATENATE(AHS!$I$17,"-"),""),IF(AHS!$J$18=$D5,CONCATENATE(AHS!$I$18,"-"),""),IF(AHS!$J$19=$D5,CONCATENATE(AHS!$I$19,"-"),""),IF(AHS!$J$20=$D5,CONCATENATE(AHS!$I$20,"-"),""),IF(AHS!$J$21=$D5,CONCATENATE(AHS!$I$21,"-"),""),IF(AHS!$J$22=$D5,CONCATENATE(AHS!$I$22,"-"),""),) | G5: =CONCATENATE(IF(AHS!$J$23=$D5,CONCATENATE(AHS!$I$23,"-"),""),IF(AHS!$J$24=$D5,CONCATENATE(AHS!$I$24,"-"),""),IF(AHS!$J$25=$D5,CONCATENATE(AHS!$I$25,"-"),""),IF(AHS!$J$26=$D5,CONCATENATE(AHS!$I$26,"-"),""),IF(AHS!$J$27=$D5,CONCATENATE(AHS!$I$27,"-"),""),IF(AHS!$J$28=$D5,CONCATENATE(AHS!$I$28,"-"),""),IF(AHS!$J$29=$D5,CONCATENATE(AHS!$I$29,"-"),""),IF(AHS!$J$30=$D5,CONCATENATE(AHS!$I$30,"-"),""),IF(AHS!$J$31=$D5,CONCATENATE(AHS!$I$31,"-"),""),IF(AHS!$J$32=$D5,CONCATENATE(AHS!$I$32,"-"),"")) | H5: =CONCATENATE(IF(AHS!$R$13=$D5,CONCATENATE(AHS!$Q$13,"-"),""),IF(AHS!$R$14=$D5,CONCATENATE(AHS!$Q$14,"-"),""),IF(AHS!$R$15=$D5,CONCATENATE(AHS!$Q$15,"-"),""),IF(AHS!$R$16=$D5,CONCATENATE(AHS!$Q$16,"-"),""),IF(AHS!$R$17=$D5,CONCATENATE(AHS!$Q$17,"-"),""),IF(AHS!$R$18=$D5,CONCATENATE(AHS!$Q$18,"-"),""),IF(AHS!$R$19=$D5,CONCATENATE(AHS!$Q$19,"-"),""),IF(AHS!$R$20=$D5,CONCATENATE(AHS!$Q$20,"-"),""),IF(AHS!$R$21=$D5,CONCATENATE(AHS!$Q$21,"-"),""),IF(AHS!$R$22=$D5,CONCATENATE(AHS!$Q$22,"-"),"")) | I5: =CONCATENATE(,IF(AHS!$R$23=$D5,CONCATENATE(AHS!$Q$23,"-"),""),IF(AHS!$R$24=$D5,CONCATENATE(AHS!$Q$24,"-"),""),IF(AHS!$R$25=$D5,CONCATENATE(AHS!$Q$25,"-"),""),IF(AHS!$R$26=$D5,CONCATENATE(AHS!$Q$26,"-"),""),IF(AHS!$R$27=$D5,CONCATENATE(AHS!$Q$27,"-"),""),IF(AHS!$R$28=$D5,CONCATENATE(AHS!$Q$28,"-"),""),IF(AHS!$R$29=$D5,CONCATENATE(AHS!$Q$29,"-"),""),IF(AHS!$R$30=$D5,CONCATENATE(AHS!$Q$30,"-"),""),IF(AHS!$R$31=$D5,CONCATENATE(AHS!$Q$31,"-"),""),IF(AHS!$R$32=$D5,CONCATENATE(AHS!$Q$32,"-"),"")) | J5: =CONCATENATE(IF(AHS!$Z$13=$D5,CONCATENATE(AHS!$Y$13,"-"),""),IF(AHS!$Z$14=$D5,CONCATENATE(AHS!$Y$14,"-"),""),IF(AHS!$Z$15=$D5,CONCATENATE(AHS!$Y$15,"-"),""),IF(AHS!$Z$16=$D5,CONCATENATE(AHS!$Y$16,"-"),""),IF(AHS!$Z$17=$D5,CONCATENATE(AHS!$Y$17,"-"),""),IF(AHS!$Z$18=$D5,CONCATENATE(AHS!$Y$18,"-"),""),IF(AHS!$Z$19=$D5,CONCATENATE(AHS!$Y$19,"-"),""),IF(AHS!$Z$20=$D5,CONCATENATE(AHS!$Y$20,"-"),""),IF(AHS!$Z$21=$D5,CONCATENATE(AHS!$Y$21,"-"),""),IF(AHS!$Z$22=$D5,CONCATENATE(AHS!$Y$22,"-"),""),"") | K5: =CONCATENATE(IF(AHS!$Z$23=$D5,CONCATENATE(AHS!$Y$23,"-"),""),IF(AHS!$Z$24=$D5,CONCATENATE(AHS!$Y$24,"-"),""),IF(AHS!$Z$25=$D5,CONCATENATE(AHS!$Y$25,"-"),""),IF(AHS!$Z$26=$D5,CONCATENATE(AHS!$Y$26,"-"),""),IF(AHS!$Z$27=$D5,CONCATENATE(AHS!$Y$27,"-"),""),IF(AHS!$Z$28=$D5,CONCATENATE(AHS!$Y$28,"-"),""),IF(AHS!$Z$29=$D5,CONCATENATE(AHS!$Y$29,"-"),""),IF(AHS!$Z$30=$D5,CONCATENATE(AHS!$Y$30,"-"),""),IF(AHS!$Z$31=$D5,CONCATENATE(AHS!$Y$31,"-"),""),IF(AHS!$Z$32=$D5,CONCATENATE(AHS!$Y$32,"-"),"")) | L5: =CONCATENATE(IF(AHS!$AH$13=$D5,CONCATENATE(AHS!$AG$13,"-"),""),IF(AHS!$AH$14=$D5,CONCATENATE(AHS!$AG$14,"-"),""),IF(AHS!$AH$15=$D5,CONCATENATE(AHS!$AG$15,"-"),""),IF(AHS!$AH$16=$D5,CONCATENATE(AHS!$AG$16,"-"),""),IF(AHS!$AH$17=$D5,CONCATENATE(AHS!$AG$17,"-"),""),IF(AHS!$AH$18=$D5,CONCATENATE(AHS!$AG$18,"-"),""),IF(AHS!$AH$19=$D5,CONCATENATE(AHS!$AG$19,"-"),""),IF(AHS!$AH$20=$D5,CONCATENATE(AHS!$AG$20,"-"),""),IF(AHS!$AH$21=$D5,CONCATENATE(AHS!$AG$21,"-"),""),IF(AHS!$AH$22=$D5,CONCATENATE(AHS!$AG$22,"-"),""),"") | M5: =CONCATENATE(IF(AHS!$AH$23=$D5,CONCATENATE(AHS!$AG$23,"-"),""),IF(AHS!$AH$24=$D5,CONCATENATE(AHS!$AG$24,"-"),""),IF(AHS!$AH$25=$D5,CONCATENATE(AHS!$AG$25,"-"),""),IF(AHS!$AH$26=$D5,CONCATENATE(AHS!$AG$26,"-"),""),IF(AHS!$AH$27=$D5,CONCATENATE(AHS!$AG$27,"-"),""),IF(AHS!$AH$28=$D5,CONCATENATE(AHS!$AG$28,"-"),""),IF(AHS!$AH$29=$D5,CONCATENATE(AHS!$AG$29,"-"),""),IF(AHS!$AH$30=$D5,CONCATENATE(AHS!$AG$30,"-"),""),IF(AHS!$AH$31=$D5,CONCATENATE(AHS!$AG$31,"-"),""),IF(AHS!$AH$32=$D5,CONCATENATE(AHS!$AG$32,"-"),"")) | N5: =CONCATENATE(F5,G5,H5,I5,J5,K5,L5,M5) | O5: 3 | P5: =IF(ISERROR(VLOOKUP($O5,$A$1:$B$100,2,FALSE)),"",VLOOKUP($O5,$A$1:$B$100,2,FALSE)) | Q5: =IF(P5="","",VLOOKUP($O5,$A$1:$E$100,5,FALSE)) | R5: =IF(P5="","",CHOOSE(VLOOKUP($O5,$A$1:$C$100,3,FALSE),AHS!$M$1,BHS!$M$1,CHS!$M$1,HMJHS!$M$1,KHS!$M$1,Kings!$M$1,MHS!$M$1,SWHS!$M$1,AMHS!$M$1,'S10'!$M$1,'S11'!$M$1,'S12'!$M$1,'S13'!$M$1,'S14'!$M$1,'S15'!$M$1,'S16'!$M$1,'S17'!$M$1,'S18'!$M$1,'S19'!$M$1,'S20'!$M$1)) | S5: =IF(P5="","",VLOOKUP($O5,$A$1:$E$100,4,FALSE)) | T5: =IF(P5="","",VLOOKUP($O5,$A$1:$N$100,14,FALSE))
A6: =IF(B6="","",COUNTIF($B$1:B5,B6)+B6) | B6: =IF(E6="","",RANK(E6,$E$1:$E$100)) | C6: 2 | D6: 1 | E6: =IF(BHS!$C$4="","",BHS!$C$4) | F6: =CONCATENATE(IF(BHS!$J$13=$D6,CONCATENATE(BHS!$I$13,"-"),""),IF(BHS!$J$14=$D6,CONCATENATE(BHS!$I$14,"-"),""),IF(BHS!$J$15=$D6,CONCATENATE(BHS!$I$15,"-"),""),IF(BHS!$J$16=$D6,CONCATENATE(BHS!$I$16,"-"),""),IF(BHS!$J$17=$D6,CONCATENATE(BHS!$I$17,"-"),""),IF(BHS!$J$18=$D6,CONCATENATE(BHS!$I$18,"-"),""),IF(BHS!$J$19=$D6,CONCATENATE(BHS!$I$19,"-"),""),IF(BHS!$J$20=$D6,CONCATENATE(BHS!$I$20,"-"),""),IF(BHS!$J$21=$D6,CONCATENATE(BHS!$I$21,"-"),""),IF(BHS!$J$22=$D6,CONCATENATE(BHS!$I$22,"-"),""),) | G6: =CONCATENATE(IF(BHS!$J$23=$D6,CONCATENATE(BHS!$I$23,"-"),""),IF(BHS!$J$24=$D6,CONCATENATE(BHS!$I$24,"-"),""),IF(BHS!$J$25=$D6,CONCATENATE(BHS!$I$25,"-"),""),IF(BHS!$J$26=$D6,CONCATENATE(BHS!$I$26,"-"),""),IF(BHS!$J$27=$D6,CONCATENATE(BHS!$I$27,"-"),""),IF(BHS!$J$28=$D6,CONCATENATE(BHS!$I$28,"-"),""),IF(BHS!$J$29=$D6,CONCATENATE(BHS!$I$29,"-"),""),IF(BHS!$J$30=$D6,CONCATENATE(BHS!$I$30,"-"),""),IF(BHS!$J$31=$D6,CONCATENATE(BHS!$I$31,"-"),""),IF(BHS!$J$32=$D6,CONCATENATE(BHS!$I$32,"-"),"")) | H6: =CONCATENATE(IF(BHS!$R$13=$D6,CONCATENATE(BHS!$Q$13,"-"),""),IF(BHS!$R$14=$D6,CONCATENATE(BHS!$Q$14,"-"),""),IF(BHS!$R$15=$D6,CONCATENATE(BHS!$Q$15,"-"),""),IF(BHS!$R$16=$D6,CONCATENATE(BHS!$Q$16,"-"),""),IF(BHS!$R$17=$D6,CONCATENATE(BHS!$Q$17,"-"),""),IF(BHS!$R$18=$D6,CONCATENATE(BHS!$Q$18,"-"),""),IF(BHS!$R$19=$D6,CONCATENATE(BHS!$Q$19,"-"),""),IF(BHS!$R$20=$D6,CONCATENATE(BHS!$Q$20,"-"),""),IF(BHS!$R$21=$D6,CONCATENATE(BHS!$Q$21,"-"),""),IF(BHS!$R$22=$D6,CONCATENATE(BHS!$Q$22,"-"),"")) | I6: =CONCATENATE(,IF(BHS!$R$23=$D6,CONCATENATE(BHS!$Q$23,"-"),""),IF(BHS!$R$24=$D6,CONCATENATE(BHS!$Q$24,"-"),""),IF(BHS!$R$25=$D6,CONCATENATE(BHS!$Q$25,"-"),""),IF(BHS!$R$26=$D6,CONCATENATE(BHS!$Q$26,"-"),""),IF(BHS!$R$27=$D6,CONCATENATE(BHS!$Q$27,"-"),""),IF(BHS!$R$28=$D6,CONCATENATE(BHS!$Q$28,"-"),""),IF(BHS!$R$29=$D6,CONCATENATE(BHS!$Q$29,"-"),""),IF(BHS!$R$30=$D6,CONCATENATE(BHS!$Q$30,"-"),""),IF(BHS!$R$31=$D6,CONCATENATE(BHS!$Q$31,"-"),""),IF(BHS!$R$32=$D6,CONCATENATE(BHS!$Q$32,"-"),"")) | J6: =CONCATENATE(IF(BHS!$Z$13=$D6,CONCATENATE(BHS!$Y$13,"-"),""),IF(BHS!$Z$14=$D6,CONCATENATE(BHS!$Y$14,"-"),""),IF(BHS!$Z$15=$D6,CONCATENATE(BHS!$Y$15,"-"),""),IF(BHS!$Z$16=$D6,CONCATENATE(BHS!$Y$16,"-"),""),IF(BHS!$Z$17=$D6,CONCATENATE(BHS!$Y$17,"-"),""),IF(BHS!$Z$18=$D6,CONCATENATE(BHS!$Y$18,"-"),""),IF(BHS!$Z$19=$D6,CONCATENATE(BHS!$Y$19,"-"),""),IF(BHS!$Z$20=$D6,CONCATENATE(BHS!$Y$20,"-"),""),IF(BHS!$Z$21=$D6,CONCATENATE(BHS!$Y$21,"-"),""),IF(BHS!$Z$22=$D6,CONCATENATE(BHS!$Y$22,"-"),""),"") | K6: =CONCATENATE(IF(BHS!$Z$23=$D6,CONCATENATE(BHS!$Y$23,"-"),""),IF(BHS!$Z$24=$D6,CONCATENATE(BHS!$Y$24,"-"),""),IF(BHS!$Z$25=$D6,CONCATENATE(BHS!$Y$25,"-"),""),IF(BHS!$Z$26=$D6,CONCATENATE(BHS!$Y$26,"-"),""),IF(BHS!$Z$27=$D6,CONCATENATE(BHS!$Y$27,"-"),""),IF(BHS!$Z$28=$D6,CONCATENATE(BHS!$Y$28,"-"),""),IF(BHS!$Z$29=$D6,CONCATENATE(BHS!$Y$29,"-"),""),IF(BHS!$Z$30=$D6,CONCATENATE(BHS!$Y$30,"-"),""),IF(BHS!$Z$31=$D6,CONCATENATE(BHS!$Y$31,"-"),""),IF(BHS!$Z$32=$D6,CONCATENATE(BHS!$Y$32,"-"),"")) | L6: =CONCATENATE(IF(BHS!$AH$13=$D6,CONCATENATE(BHS!$AG$13,"-"),""),IF(BHS!$AH$14=$D6,CONCATENATE(BHS!$AG$14,"-"),""),IF(BHS!$AH$15=$D6,CONCATENATE(BHS!$AG$15,"-"),""),IF(BHS!$AH$16=$D6,CONCATENATE(BHS!$AG$16,"-"),""),IF(BHS!$AH$17=$D6,CONCATENATE(BHS!$AG$17,"-"),""),IF(BHS!$AH$18=$D6,CONCATENATE(BHS!$AG$18,"-"),""),IF(BHS!$AH$19=$D6,CONCATENATE(BHS!$AG$19,"-"),""),IF(BHS!$AH$20=$D6,CONCATENATE(BHS!$AG$20,"-"),""),IF(BHS!$AH$21=$D6,CONCATENATE(BHS!$AG$21,"-"),""),IF(BHS!$AH$22=$D6,CONCATENATE(BHS!$AG$22,"-"),""),"") | M6: =CONCATENATE(IF(BHS!$AH$23=$D6,CONCATENATE(BHS!$AG$23,"-"),""),IF(BHS!$AH$24=$D6,CONCATENATE(BHS!$AG$24,"-"),""),IF(BHS!$AH$25=$D6,CONCATENATE(BHS!$AG$25,"-"),""),IF(BHS!$AH$26=$D6,CONCATENATE(BHS!$AG$26,"-"),""),IF(BHS!$AH$27=$D6,CONCATENATE(BHS!$AG$27,"-"),""),IF(BHS!$AH$28=$D6,CONCATENATE(BHS!$AG$28,"-"),""),IF(BHS!$AH$29=$D6,CONCATENATE(BHS!$AG$29,"-"),""),IF(BHS!$AH$30=$D6,CONCATENATE(BHS!$AG$30,"-"),""),IF(BHS!$AH$31=$D6,CONCATENATE(BHS!$AG$31,"-"),""),IF(BHS!$AH$32=$D6,CONCATENATE(BHS!$AG$32,"-"),"")) | N6: =CONCATENATE(F6,G6,H6,I6,J6,K6,L6,M6) | O6: 4 | P6: =IF(ISERROR(VLOOKUP($O6,$A$1:$B$100,2,FALSE)),"",VLOOKUP($O6,$A$1:$B$100,2,FALSE)) | Q6: =IF(P6="","",VLOOKUP($O6,$A$1:$E$100,5,FALSE)) | R6: =IF(P6="","",CHOOSE(VLOOKUP($O6,$A$1:$C$100,3,FALSE),AHS!$M$1,BHS!$M$1,CHS!$M$1,HMJHS!$M$1,KHS!$M$1,Kings!$M$1,MHS!$M$1,SWHS!$M$1,AMHS!$M$1,'S10'!$M$1,'S11'!$M$1,'S12'!$M$1,'S13'!$M$1,'S14'!$M$1,'S15'!$M$1,'S16'!$M$1,'S17'!$M$1,'S18'!$M$1,'S19'!$M$1,'S20'!$M$1)) | S6: =IF(P6="","",VLOOKUP($O6,$A$1:$E$100,4,FALSE)) | T6: =IF(P6="","",VLOOKUP($O6,$A$1:$N$100,14,FALSE))
A7: =IF(B7="","",COUNTIF($B$1:B6,B7)+B7) | B7: =IF(E7="","",RANK(E7,$E$1:$E$100)) | C7: 2 | D7: 2 | E7: =IF(BHS!$C$5="","",BHS!$C$5) | F7: =CONCATENATE(IF(BHS!$J$13=$D7,CONCATENATE(BHS!$I$13,"-"),""),IF(BHS!$J$14=$D7,CONCATENATE(BHS!$I$14,"-"),""),IF(BHS!$J$15=$D7,CONCATENATE(BHS!$I$15,"-"),""),IF(BHS!$J$16=$D7,CONCATENATE(BHS!$I$16,"-"),""),IF(BHS!$J$17=$D7,CONCATENATE(BHS!$I$17,"-"),""),IF(BHS!$J$18=$D7,CONCATENATE(BHS!$I$18,"-"),""),IF(BHS!$J$19=$D7,CONCATENATE(BHS!$I$19,"-"),""),IF(BHS!$J$20=$D7,CONCATENATE(BHS!$I$20,"-"),""),IF(BHS!$J$21=$D7,CONCATENATE(BHS!$I$21,"-"),""),IF(BHS!$J$22=$D7,CONCATENATE(BHS!$I$22,"-"),""),) | G7: =CONCATENATE(IF(BHS!$J$23=$D7,CONCATENATE(BHS!$I$23,"-"),""),IF(BHS!$J$24=$D7,CONCATENATE(BHS!$I$24,"-"),""),IF(BHS!$J$25=$D7,CONCATENATE(BHS!$I$25,"-"),""),IF(BHS!$J$26=$D7,CONCATENATE(BHS!$I$26,"-"),""),IF(BHS!$J$27=$D7,CONCATENATE(BHS!$I$27,"-"),""),IF(BHS!$J$28=$D7,CONCATENATE(BHS!$I$28,"-"),""),IF(BHS!$J$29=$D7,CONCATENATE(BHS!$I$29,"-"),""),IF(BHS!$J$30=$D7,CONCATENATE(BHS!$I$30,"-"),""),IF(BHS!$J$31=$D7,CONCATENATE(BHS!$I$31,"-"),""),IF(BHS!$J$32=$D7,CONCATENATE(BHS!$I$32,"-"),"")) | H7: =CONCATENATE(IF(BHS!$R$13=$D7,CONCATENATE(BHS!$Q$13,"-"),""),IF(BHS!$R$14=$D7,CONCATENATE(BHS!$Q$14,"-"),""),IF(BHS!$R$15=$D7,CONCATENATE(BHS!$Q$15,"-"),""),IF(BHS!$R$16=$D7,CONCATENATE(BHS!$Q$16,"-"),""),IF(BHS!$R$17=$D7,CONCATENATE(BHS!$Q$17,"-"),""),IF(BHS!$R$18=$D7,CONCATENATE(BHS!$Q$18,"-"),""),IF(BHS!$R$19=$D7,CONCATENATE(BHS!$Q$19,"-"),""),IF(BHS!$R$20=$D7,CONCATENATE(BHS!$Q$20,"-"),""),IF(BHS!$R$21=$D7,CONCATENATE(BHS!$Q$21,"-"),""),IF(BHS!$R$22=$D7,CONCATENATE(BHS!$Q$22,"-"),"")) | I7: =CONCATENATE(,IF(BHS!$R$23=$D7,CONCATENATE(BHS!$Q$23,"-"),""),IF(BHS!$R$24=$D7,CONCATENATE(BHS!$Q$24,"-"),""),IF(BHS!$R$25=$D7,CONCATENATE(BHS!$Q$25,"-"),""),IF(BHS!$R$26=$D7,CONCATENATE(BHS!$Q$26,"-"),""),IF(BHS!$R$27=$D7,CONCATENATE(BHS!$Q$27,"-"),""),IF(BHS!$R$28=$D7,CONCATENATE(BHS!$Q$28,"-"),""),IF(BHS!$R$29=$D7,CONCATENATE(BHS!$Q$29,"-"),""),IF(BHS!$R$30=$D7,CONCATENATE(BHS!$Q$30,"-"),""),IF(BHS!$R$31=$D7,CONCATENATE(BHS!$Q$31,"-"),""),IF(BHS!$R$32=$D7,CONCATENATE(BHS!$Q$32,"-"),"")) | J7: =CONCATENATE(IF(BHS!$Z$13=$D7,CONCATENATE(BHS!$Y$13,"-"),""),IF(BHS!$Z$14=$D7,CONCATENATE(BHS!$Y$14,"-"),""),IF(BHS!$Z$15=$D7,CONCATENATE(BHS!$Y$15,"-"),""),IF(BHS!$Z$16=$D7,CONCATENATE(BHS!$Y$16,"-"),""),IF(BHS!$Z$17=$D7,CONCATENATE(BHS!$Y$17,"-"),""),IF(BHS!$Z$18=$D7,CONCATENATE(BHS!$Y$18,"-"),""),IF(BHS!$Z$19=$D7,CONCATENATE(BHS!$Y$19,"-"),""),IF(BHS!$Z$20=$D7,CONCATENATE(BHS!$Y$20,"-"),""),IF(BHS!$Z$21=$D7,CONCATENATE(BHS!$Y$21,"-"),""),IF(BHS!$Z$22=$D7,CONCATENATE(BHS!$Y$22,"-"),""),"") | K7: =CONCATENATE(IF(BHS!$Z$23=$D7,CONCATENATE(BHS!$Y$23,"-"),""),IF(BHS!$Z$24=$D7,CONCATENATE(BHS!$Y$24,"-"),""),IF(BHS!$Z$25=$D7,CONCATENATE(BHS!$Y$25,"-"),""),IF(BHS!$Z$26=$D7,CONCATENATE(BHS!$Y$26,"-"),""),IF(BHS!$Z$27=$D7,CONCATENATE(BHS!$Y$27,"-"),""),IF(BHS!$Z$28=$D7,CONCATENATE(BHS!$Y$28,"-"),""),IF(BHS!$Z$29=$D7,CONCATENATE(BHS!$Y$29,"-"),""),IF(BHS!$Z$30=$D7,CONCATENATE(BHS!$Y$30,"-"),""),IF(BHS!$Z$31=$D7,CONCATENATE(BHS!$Y$31,"-"),""),IF(BHS!$Z$32=$D7,CONCATENATE(BHS!$Y$32,"-"),"")) | L7: =CONCATENATE(IF(BHS!$AH$13=$D7,CONCATENATE(BHS!$AG$13,"-"),""),IF(BHS!$AH$14=$D7,CONCATENATE(BHS!$AG$14,"-"),""),IF(BHS!$AH$15=$D7,CONCATENATE(BHS!$AG$15,"-"),""),IF(BHS!$AH$16=$D7,CONCATENATE(BHS!$AG$16,"-"),""),IF(BHS!$AH$17=$D7,CONCATENATE(BHS!$AG$17,"-"),""),IF(BHS!$AH$18=$D7,CONCATENATE(BHS!$AG$18,"-"),""),IF(BHS!$AH$19=$D7,CONCATENATE(BHS!$AG$19,"-"),""),IF(BHS!$AH$20=$D7,CONCATENATE(BHS!$AG$20,"-"),""),IF(BHS!$AH$21=$D7,CONCATENATE(BHS!$AG$21,"-"),""),IF(BHS!$AH$22=$D7,CONCATENATE(BHS!$AG$22,"-"),""),"") | M7: =CONCATENATE(IF(BHS!$AH$23=$D7,CONCATENATE(BHS!$AG$23,"-"),""),IF(BHS!$AH$24=$D7,CONCATENATE(BHS!$AG$24,"-"),""),IF(BHS!$AH$25=$D7,CONCATENATE(BHS!$AG$25,"-"),""),IF(BHS!$AH$26=$D7,CONCATENATE(BHS!$AG$26,"-"),""),IF(BHS!$AH$27=$D7,CONCATENATE(BHS!$AG$27,"-"),""),IF(BHS!$AH$28=$D7,CONCATENATE(BHS!$AG$28,"-"),""),IF(BHS!$AH$29=$D7,CONCATENATE(BHS!$AG$29,"-"),""),IF(BHS!$AH$30=$D7,CONCATENATE(BHS!$AG$30,"-"),""),IF(BHS!$AH$31=$D7,CONCATENATE(BHS!$AG$31,"-"),""),IF(BHS!$AH$32=$D7,CONCATENATE(BHS!$AG$32,"-"),"")) | N7: =CONCATENATE(F7,G7,H7,I7,J7,K7,L7,M7) | O7: 5 | P7: =IF(ISERROR(VLOOKUP($O7,$A$1:$B$100,2,FALSE)),"",VLOOKUP($O7,$A$1:$B$100,2,FALSE)) | Q7: =IF(P7="","",VLOOKUP($O7,$A$1:$E$100,5,FALSE)) | R7: =IF(P7="","",CHOOSE(VLOOKUP($O7,$A$1:$C$100,3,FALSE),AHS!$M$1,BHS!$M$1,CHS!$M$1,HMJHS!$M$1,KHS!$M$1,Kings!$M$1,MHS!$M$1,SWHS!$M$1,AMHS!$M$1,'S10'!$M$1,'S11'!$M$1,'S12'!$M$1,'S13'!$M$1,'S14'!$M$1,'S15'!$M$1,'S16'!$M$1,'S17'!$M$1,'S18'!$M$1,'S19'!$M$1,'S20'!$M$1)) | S7: =IF(P7="","",VLOOKUP($O7,$A$1:$E$100,4,FALSE)) | T7: =IF(P7="","",VLOOKUP($O7,$A$1:$N$100,14,FALSE))
A8: =IF(B8="","",COUNTIF($B$1:B7,B8)+B8) | B8: =IF(E8="","",RANK(E8,$E$1:$E$100)) | C8: 2 | D8: 3 | E8: =IF(BHS!$C$6="","",BHS!$C$6) | F8: =CONCATENATE(IF(BHS!$J$13=$D8,CONCATENATE(BHS!$I$13,"-"),""),IF(BHS!$J$14=$D8,CONCATENATE(BHS!$I$14,"-"),""),IF(BHS!$J$15=$D8,CONCATENATE(BHS!$I$15,"-"),""),IF(BHS!$J$16=$D8,CONCATENATE(BHS!$I$16,"-"),""),IF(BHS!$J$17=$D8,CONCATENATE(BHS!$I$17,"-"),""),IF(BHS!$J$18=$D8,CONCATENATE(BHS!$I$18,"-"),""),IF(BHS!$J$19=$D8,CONCATENATE(BHS!$I$19,"-"),""),IF(BHS!$J$20=$D8,CONCATENATE(BHS!$I$20,"-"),""),IF(BHS!$J$21=$D8,CONCATENATE(BHS!$I$21,"-"),""),IF(BHS!$J$22=$D8,CONCATENATE(BHS!$I$22,"-"),""),) | G8: =CONCATENATE(IF(BHS!$J$23=$D8,CONCATENATE(BHS!$I$23,"-"),""),IF(BHS!$J$24=$D8,CONCATENATE(BHS!$I$24,"-"),""),IF(BHS!$J$25=$D8,CONCATENATE(BHS!$I$25,"-"),""),IF(BHS!$J$26=$D8,CONCATENATE(BHS!$I$26,"-"),""),IF(BHS!$J$27=$D8,CONCATENATE(BHS!$I$27,"-"),""),IF(BHS!$J$28=$D8,CONCATENATE(BHS!$I$28,"-"),""),IF(BHS!$J$29=$D8,CONCATENATE(BHS!$I$29,"-"),""),IF(BHS!$J$30=$D8,CONCATENATE(BHS!$I$30,"-"),""),IF(BHS!$J$31=$D8,CONCATENATE(BHS!$I$31,"-"),""),IF(BHS!$J$32=$D8,CONCATENATE(BHS!$I$32,"-"),"")) | H8: =CONCATENATE(IF(BHS!$R$13=$D8,CONCATENATE(BHS!$Q$13,"-"),""),IF(BHS!$R$14=$D8,CONCATENATE(BHS!$Q$14,"-"),""),IF(BHS!$R$15=$D8,CONCATENATE(BHS!$Q$15,"-"),""),IF(BHS!$R$16=$D8,CONCATENATE(BHS!$Q$16,"-"),""),IF(BHS!$R$17=$D8,CONCATENATE(BHS!$Q$17,"-"),""),IF(BHS!$R$18=$D8,CONCATENATE(BHS!$Q$18,"-"),""),IF(BHS!$R$19=$D8,CONCATENATE(BHS!$Q$19,"-"),""),IF(BHS!$R$20=$D8,CONCATENATE(BHS!$Q$20,"-"),""),IF(BHS!$R$21=$D8,CONCATENATE(BHS!$Q$21,"-"),""),IF(BHS!$R$22=$D8,CONCATENATE(BHS!$Q$22,"-"),"")) | I8: =CONCATENATE(,IF(BHS!$R$23=$D8,CONCATENATE(BHS!$Q$23,"-"),""),IF(BHS!$R$24=$D8,CONCATENATE(BHS!$Q$24,"-"),""),IF(BHS!$R$25=$D8,CONCATENATE(BHS!$Q$25,"-"),""),IF(BHS!$R$26=$D8,CONCATENATE(BHS!$Q$26,"-"),""),IF(BHS!$R$27=$D8,CONCATENATE(BHS!$Q$27,"-"),""),IF(BHS!$R$28=$D8,CONCATENATE(BHS!$Q$28,"-"),""),IF(BHS!$R$29=$D8,CONCATENATE(BHS!$Q$29,"-"),""),IF(BHS!$R$30=$D8,CONCATENATE(BHS!$Q$30,"-"),""),IF(BHS!$R$31=$D8,CONCATENATE(BHS!$Q$31,"-"),""),IF(BHS!$R$32=$D8,CONCATENATE(BHS!$Q$32,"-"),"")) | J8: =CONCATENATE(IF(BHS!$Z$13=$D8,CONCATENATE(BHS!$Y$13,"-"),""),IF(BHS!$Z$14=$D8,CONCATENATE(BHS!$Y$14,"-"),""),IF(BHS!$Z$15=$D8,CONCATENATE(BHS!$Y$15,"-"),""),IF(BHS!$Z$16=$D8,CONCATENATE(BHS!$Y$16,"-"),""),IF(BHS!$Z$17=$D8,CONCATENATE(BHS!$Y$17,"-"),""),IF(BHS!$Z$18=$D8,CONCATENATE(BHS!$Y$18,"-"),""),IF(BHS!$Z$19=$D8,CONCATENATE(BHS!$Y$19,"-"),""),IF(BHS!$Z$20=$D8,CONCATENATE(BHS!$Y$20,"-"),""),IF(BHS!$Z$21=$D8,CONCATENATE(BHS!$Y$21,"-"),""),IF(BHS!$Z$22=$D8,CONCATENATE(BHS!$Y$22,"-"),""),"") | K8: =CONCATENATE(IF(BHS!$Z$23=$D8,CONCATENATE(BHS!$Y$23,"-"),""),IF(BHS!$Z$24=$D8,CONCATENATE(BHS!$Y$24,"-"),""),IF(BHS!$Z$25=$D8,CONCATENATE(BHS!$Y$25,"-"),""),IF(BHS!$Z$26=$D8,CONCATENATE(BHS!$Y$26,"-"),""),IF(BHS!$Z$27=$D8,CONCATENATE(BHS!$Y$27,"-"),""),IF(BHS!$Z$28=$D8,CONCATENATE(BHS!$Y$28,"-"),""),IF(BHS!$Z$29=$D8,CONCATENATE(BHS!$Y$29,"-"),""),IF(BHS!$Z$30=$D8,CONCATENATE(BHS!$Y$30,"-"),""),IF(BHS!$Z$31=$D8,CONCATENATE(BHS!$Y$31,"-"),""),IF(BHS!$Z$32=$D8,CONCATENATE(BHS!$Y$32,"-"),"")) | L8: =CONCATENATE(IF(BHS!$AH$13=$D8,CONCATENATE(BHS!$AG$13,"-"),""),IF(BHS!$AH$14=$D8,CONCATENATE(BHS!$AG$14,"-"),""),IF(BHS!$AH$15=$D8,CONCATENATE(BHS!$AG$15,"-"),""),IF(BHS!$AH$16=$D8,CONCATENATE(BHS!$AG$16,"-"),""),IF(BHS!$AH$17=$D8,CONCATENATE(BHS!$AG$17,"-"),""),IF(BHS!$AH$18=$D8,CONCATENATE(BHS!$AG$18,"-"),""),IF(BHS!$AH$19=$D8,CONCATENATE(BHS!$AG$19,"-"),""),IF(BHS!$AH$20=$D8,CONCATENATE(BHS!$AG$20,"-"),""),IF(BHS!$AH$21=$D8,CONCATENATE(BHS!$AG$21,"-"),""),IF(BHS!$AH$22=$D8,CONCATENATE(BHS!$AG$22,"-"),""),"") | M8: =CONCATENATE(IF(BHS!$AH$23=$D8,CONCATENATE(BHS!$AG$23,"-"),""),IF(BHS!$AH$24=$D8,CONCATENATE(BHS!$AG$24,"-"),""),IF(BHS!$AH$25=$D8,CONCATENATE(BHS!$AG$25,"-"),""),IF(BHS!$AH$26=$D8,CONCATENATE(BHS!$AG$26,"-"),""),IF(BHS!$AH$27=$D8,CONCATENATE(BHS!$AG$27,"-"),""),IF(BHS!$AH$28=$D8,CONCATENATE(BHS!$AG$28,"-"),""),IF(BHS!$AH$29=$D8,CONCATENATE(BHS!$AG$29,"-"),""),IF(BHS!$AH$30=$D8,CONCATENATE(BHS!$AG$30,"-"),""),IF(BHS!$AH$31=$D8,CONCATENATE(BHS!$AG$31,"-"),""),IF(BHS!$AH$32=$D8,CONCATENATE(BHS!$AG$32,"-"),"")) | N8: =CONCATENATE(F8,G8,H8,I8,J8,K8,L8,M8) | O8: 6 | P8: =IF(ISERROR(VLOOKUP($O8,$A$1:$B$100,2,FALSE)),"",VLOOKUP($O8,$A$1:$B$100,2,FALSE)) | Q8: =IF(P8="","",VLOOKUP($O8,$A$1:$E$100,5,FALSE)) | R8: =IF(P8="","",CHOOSE(VLOOKUP($O8,$A$1:$C$100,3,FALSE),AHS!$M$1,BHS!$M$1,CHS!$M$1,HMJHS!$M$1,KHS!$M$1,Kings!$M$1,MHS!$M$1,SWHS!$M$1,AMHS!$M$1,'S10'!$M$1,'S11'!$M$1,'S12'!$M$1,'S13'!$M$1,'S14'!$M$1,'S15'!$M$1,'S16'!$M$1,'S17'!$M$1,'S18'!$M$1,'S19'!$M$1,'S20'!$M$1)) | S8: =IF(P8="","",VLOOKUP($O8,$A$1:$E$100,4,FALSE)) | T8: =IF(P8="","",VLOOKUP($O8,$A$1:$N$100,14,FALSE))
A9: =IF(B9="","",COUNTIF($B$1:B8,B9)+B9) | B9: =IF(E9="","",RANK(E9,$E$1:$E$100)) | C9: 2 | D9: 4 | E9: =IF(BHS!$C$7="","",BHS!$C$7) | F9: =CONCATENATE(IF(BHS!$J$13=$D9,CONCATENATE(BHS!$I$13,"-"),""),IF(BHS!$J$14=$D9,CONCATENATE(BHS!$I$14,"-"),""),IF(BHS!$J$15=$D9,CONCATENATE(BHS!$I$15,"-"),""),IF(BHS!$J$16=$D9,CONCATENATE(BHS!$I$16,"-"),""),IF(BHS!$J$17=$D9,CONCATENATE(BHS!$I$17,"-"),""),IF(BHS!$J$18=$D9,CONCATENATE(BHS!$I$18,"-"),""),IF(BHS!$J$19=$D9,CONCATENATE(BHS!$I$19,"-"),""),IF(BHS!$J$20=$D9,CONCATENATE(BHS!$I$20,"-"),""),IF(BHS!$J$21=$D9,CONCATENATE(BHS!$I$21,"-"),""),IF(BHS!$J$22=$D9,CONCATENATE(BHS!$I$22,"-"),""),) | G9: =CONCATENATE(IF(BHS!$J$23=$D9,CONCATENATE(BHS!$I$23,"-"),""),IF(BHS!$J$24=$D9,CONCATENATE(BHS!$I$24,"-"),""),IF(BHS!$J$25=$D9,CONCATENATE(BHS!$I$25,"-"),""),IF(BHS!$J$26=$D9,CONCATENATE(BHS!$I$26,"-"),""),IF(BHS!$J$27=$D9,CONCATENATE(BHS!$I$27,"-"),""),IF(BHS!$J$28=$D9,CONCATENATE(BHS!$I$28,"-"),""),IF(BHS!$J$29=$D9,CONCATENATE(BHS!$I$29,"-"),""),IF(BHS!$J$30=$D9,CONCATENATE(BHS!$I$30,"-"),""),IF(BHS!$J$31=$D9,CONCATENATE(BHS!$I$31,"-"),""),IF(BHS!$J$32=$D9,CONCATENATE(BHS!$I$32,"-"),"")) | H9: =CONCATENATE(IF(BHS!$R$13=$D9,CONCATENATE(BHS!$Q$13,"-"),""),IF(BHS!$R$14=$D9,CONCATENATE(BHS!$Q$14,"-"),""),IF(BHS!$R$15=$D9,CONCATENATE(BHS!$Q$15,"-"),""),IF(BHS!$R$16=$D9,CONCATENATE(BHS!$Q$16,"-"),""),IF(BHS!$R$17=$D9,CONCATENATE(BHS!$Q$17,"-"),""),IF(BHS!$R$18=$D9,CONCATENATE(BHS!$Q$18,"-"),""),IF(BHS!$R$19=$D9,CONCATENATE(BHS!$Q$19,"-"),""),IF(BHS!$R$20=$D9,CONCATENATE(BHS!$Q$20,"-"),""),IF(BHS!$R$21=$D9,CONCATENATE(BHS!$Q$21,"-"),""),IF(BHS!$R$22=$D9,CONCATENATE(BHS!$Q$22,"-"),"")) | I9: =CONCATENATE(,IF(BHS!$R$23=$D9,CONCATENATE(BHS!$Q$23,"-"),""),IF(BHS!$R$24=$D9,CONCATENATE(BHS!$Q$24,"-"),""),IF(BHS!$R$25=$D9,CONCATENATE(BHS!$Q$25,"-"),""),IF(BHS!$R$26=$D9,CONCATENATE(BHS!$Q$26,"-"),""),IF(BHS!$R$27=$D9,CONCATENATE(BHS!$Q$27,"-"),""),IF(BHS!$R$28=$D9,CONCATENATE(BHS!$Q$28,"-"),""),IF(BHS!$R$29=$D9,CONCATENATE(BHS!$Q$29,"-"),""),IF(BHS!$R$30=$D9,CONCATENATE(BHS!$Q$30,"-"),""),IF(BHS!$R$31=$D9,CONCATENATE(BHS!$Q$31,"-"),""),IF(BHS!$R$32=$D9,CONCATENATE(BHS!$Q$32,"-"),"")) | J9: =CONCATENATE(IF(BHS!$Z$13=$D9,CONCATENATE(BHS!$Y$13,"-"),""),IF(BHS!$Z$14=$D9,CONCATENATE(BHS!$Y$14,"-"),""),IF(BHS!$Z$15=$D9,CONCATENATE(BHS!$Y$15,"-"),""),IF(BHS!$Z$16=$D9,CONCATENATE(BHS!$Y$16,"-"),""),IF(BHS!$Z$17=$D9,CONCATENATE(BHS!$Y$17,"-"),""),IF(BHS!$Z$18=$D9,CONCATENATE(BHS!$Y$18,"-"),""),IF(BHS!$Z$19=$D9,CONCATENATE(BHS!$Y$19,"-"),""),IF(BHS!$Z$20=$D9,CONCATENATE(BHS!$Y$20,"-"),""),IF(BHS!$Z$21=$D9,CONCATENATE(BHS!$Y$21,"-"),""),IF(BHS!$Z$22=$D9,CONCATENATE(BHS!$Y$22,"-"),""),"") | K9: =CONCATENATE(IF(BHS!$Z$23=$D9,CONCATENATE(BHS!$Y$23,"-"),""),IF(BHS!$Z$24=$D9,CONCATENATE(BHS!$Y$24,"-"),""),IF(BHS!$Z$25=$D9,CONCATENATE(BHS!$Y$25,"-"),""),IF(BHS!$Z$26=$D9,CONCATENATE(BHS!$Y$26,"-"),""),IF(BHS!$Z$27=$D9,CONCATENATE(BHS!$Y$27,"-"),""),IF(BHS!$Z$28=$D9,CONCATENATE(BHS!$Y$28,"-"),""),IF(BHS!$Z$29=$D9,CONCATENATE(BHS!$Y$29,"-"),""),IF(BHS!$Z$30=$D9,CONCATENATE(BHS!$Y$30,"-"),""),IF(BHS!$Z$31=$D9,CONCATENATE(BHS!$Y$31,"-"),""),IF(BHS!$Z$32=$D9,CONCATENATE(BHS!$Y$32,"-"),"")) | L9: =CONCATENATE(IF(BHS!$AH$13=$D9,CONCATENATE(BHS!$AG$13,"-"),""),IF(BHS!$AH$14=$D9,CONCATENATE(BHS!$AG$14,"-"),""),IF(BHS!$AH$15=$D9,CONCATENATE(BHS!$AG$15,"-"),""),IF(BHS!$AH$16=$D9,CONCATENATE(BHS!$AG$16,"-"),""),IF(BHS!$AH$17=$D9,CONCATENATE(BHS!$AG$17,"-"),""),IF(BHS!$AH$18=$D9,CONCATENATE(BHS!$AG$18,"-"),""),IF(BHS!$AH$19=$D9,CONCATENATE(BHS!$AG$19,"-"),""),IF(BHS!$AH$20=$D9,CONCATENATE(BHS!$AG$20,"-"),""),IF(BHS!$AH$21=$D9,CONCATENATE(BHS!$AG$21,"-"),""),IF(BHS!$AH$22=$D9,CONCATENATE(BHS!$AG$22,"-"),""),"") | M9: =CONCATENATE(IF(BHS!$AH$23=$D9,CONCATENATE(BHS!$AG$23,"-"),""),IF(BHS!$AH$24=$D9,CONCATENATE(BHS!$AG$24,"-"),""),IF(BHS!$AH$25=$D9,CONCATENATE(BHS!$AG$25,"-"),""),IF(BHS!$AH$26=$D9,CONCATENATE(BHS!$AG$26,"-"),""),IF(BHS!$AH$27=$D9,CONCATENATE(BHS!$AG$27,"-"),""),IF(BHS!$AH$28=$D9,CONCATENATE(BHS!$AG$28,"-"),""),IF(BHS!$AH$29=$D9,CONCATENATE(BHS!$AG$29,"-"),""),IF(BHS!$AH$30=$D9,CONCATENATE(BHS!$AG$30,"-"),""),IF(BHS!$AH$31=$D9,CONCATENATE(BHS!$AG$31,"-"),""),IF(BHS!$AH$32=$D9,CONCATENATE(BHS!$AG$32,"-"),"")) | N9: =CONCATENATE(F9,G9,H9,I9,J9,K9,L9,M9) | O9: 7 | P9: =IF(ISERROR(VLOOKUP($O9,$A$1:$B$100,2,FALSE)),"",VLOOKUP($O9,$A$1:$B$100,2,FALSE)) | Q9: =IF(P9="","",VLOOKUP($O9,$A$1:$E$100,5,FALSE)) | R9: =IF(P9="","",CHOOSE(VLOOKUP($O9,$A$1:$C$100,3,FALSE),AHS!$M$1,BHS!$M$1,CHS!$M$1,HMJHS!$M$1,KHS!$M$1,Kings!$M$1,MHS!$M$1,SWHS!$M$1,AMHS!$M$1,'S10'!$M$1,'S11'!$M$1,'S12'!$M$1,'S13'!$M$1,'S14'!$M$1,'S15'!$M$1,'S16'!$M$1,'S17'!$M$1,'S18'!$M$1,'S19'!$M$1,'S20'!$M$1)) | S9: =IF(P9="","",VLOOKUP($O9,$A$1:$E$100,4,FALSE)) | T9: =IF(P9="","",VLOOKUP($O9,$A$1:$N$100,14,FALSE))
A10: =IF(B10="","",COUNTIF($B$1:B9,B10)+B10) | B10: =IF(E10="","",RANK(E10,$E$1:$E$100)) | C10: 2 | D10: 5 | E10: =IF(BHS!$C$8="","",BHS!$C$8) | F10: =CONCATENATE(IF(BHS!$J$13=$D10,CONCATENATE(BHS!$I$13,"-"),""),IF(BHS!$J$14=$D10,CONCATENATE(BHS!$I$14,"-"),""),IF(BHS!$J$15=$D10,CONCATENATE(BHS!$I$15,"-"),""),IF(BHS!$J$16=$D10,CONCATENATE(BHS!$I$16,"-"),""),IF(BHS!$J$17=$D10,CONCATENATE(BHS!$I$17,"-"),""),IF(BHS!$J$18=$D10,CONCATENATE(BHS!$I$18,"-"),""),IF(BHS!$J$19=$D10,CONCATENATE(BHS!$I$19,"-"),""),IF(BHS!$J$20=$D10,CONCATENATE(BHS!$I$20,"-"),""),IF(BHS!$J$21=$D10,CONCATENATE(BHS!$I$21,"-"),""),IF(BHS!$J$22=$D10,CONCATENATE(BHS!$I$22,"-"),""),) | G10: =CONCATENATE(IF(BHS!$J$23=$D10,CONCATENATE(BHS!$I$23,"-"),""),IF(BHS!$J$24=$D10,CONCATENATE(BHS!$I$24,"-"),""),IF(BHS!$J$25=$D10,CONCATENATE(BHS!$I$25,"-"),""),IF(BHS!$J$26=$D10,CONCATENATE(BHS!$I$26,"-"),""),IF(BHS!$J$27=$D10,CONCATENATE(BHS!$I$27,"-"),""),IF(BHS!$J$28=$D10,CONCATENATE(BHS!$I$28,"-"),""),IF(BHS!$J$29=$D10,CONCATENATE(BHS!$I$29,"-"),""),IF(BHS!$J$30=$D10,CONCATENATE(BHS!$I$30,"-"),""),IF(BHS!$J$31=$D10,CONCATENATE(BHS!$I$31,"-"),""),IF(BHS!$J$32=$D10,CONCATENATE(BHS!$I$32,"-"),"")) | H10: =CONCATENATE(IF(BHS!$R$13=$D10,CONCATENATE(BHS!$Q$13,"-"),""),IF(BHS!$R$14=$D10,CONCATENATE(BHS!$Q$14,"-"),""),IF(BHS!$R$15=$D10,CONCATENATE(BHS!$Q$15,"-"),""),IF(BHS!$R$16=$D10,CONCATENATE(BHS!$Q$16,"-"),""),IF(BHS!$R$17=$D10,CONCATENATE(BHS!$Q$17,"-"),""),IF(BHS!$R$18=$D10,CONCATENATE(BHS!$Q$18,"-"),""),IF(BHS!$R$19=$D10,CONCATENATE(BHS!$Q$19,"-"),""),IF(BHS!$R$20=$D10,CONCATENATE(BHS!$Q$20,"-"),""),IF(BHS!$R$21=$D10,CONCATENATE(BHS!$Q$21,"-"),""),IF(BHS!$R$22=$D10,CONCATENATE(BHS!$Q$22,"-"),"")) | I10: =CONCATENATE(,IF(BHS!$R$23=$D10,CONCATENATE(BHS!$Q$23,"-"),""),IF(BHS!$R$24=$D10,CONCATENATE(BHS!$Q$24,"-"),""),IF(BHS!$R$25=$D10,CONCATENATE(BHS!$Q$25,"-"),""),IF(BHS!$R$26=$D10,CONCATENATE(BHS!$Q$26,"-"),""),IF(BHS!$R$27=$D10,CONCATENATE(BHS!$Q$27,"-"),""),IF(BHS!$R$28=$D10,CONCATENATE(BHS!$Q$28,"-"),""),IF(BHS!$R$29=$D10,CONCATENATE(BHS!$Q$29,"-"),""),IF(BHS!$R$30=$D10,CONCATENATE(BHS!$Q$30,"-"),""),IF(BHS!$R$31=$D10,CONCATENATE(BHS!$Q$31,"-"),""),IF(BHS!$R$32=$D10,CONCATENATE(BHS!$Q$32,"-"),"")) | J10: =CONCATENATE(IF(BHS!$Z$13=$D10,CONCATENATE(BHS!$Y$13,"-"),""),IF(BHS!$Z$14=$D10,CONCATENATE(BHS!$Y$14,"-"),""),IF(BHS!$Z$15=$D10,CONCATENATE(BHS!$Y$15,"-"),""),IF(BHS!$Z$16=$D10,CONCATENATE(BHS!$Y$16,"-"),""),IF(BHS!$Z$17=$D10,CONCATENATE(BHS!$Y$17,"-"),""),IF(BHS!$Z$18=$D10,CONCATENATE(BHS!$Y$18,"-"),""),IF(BHS!$Z$19=$D10,CONCATENATE(BHS!$Y$19,"-"),""),IF(BHS!$Z$20=$D10,CONCATENATE(BHS!$Y$20,"-"),""),IF(BHS!$Z$21=$D10,CONCATENATE(BHS!$Y$21,"-"),""),IF(BHS!$Z$22=$D10,CONCATENATE(BHS!$Y$22,"-"),""),"") | K10: =CONCATENATE(IF(BHS!$Z$23=$D10,CONCATENATE(BHS!$Y$23,"-"),""),IF(BHS!$Z$24=$D10,CONCATENATE(BHS!$Y$24,"-"),""),IF(BHS!$Z$25=$D10,CONCATENATE(BHS!$Y$25,"-"),""),IF(BHS!$Z$26=$D10,CONCATENATE(BHS!$Y$26,"-"),""),IF(BHS!$Z$27=$D10,CONCATENATE(BHS!$Y$27,"-"),""),IF(BHS!$Z$28=$D10,CONCATENATE(BHS!$Y$28,"-"),""),IF(BHS!$Z$29=$D10,CONCATENATE(BHS!$Y$29,"-"),""),IF(BHS!$Z$30=$D10,CONCATENATE(BHS!$Y$30,"-"),""),IF(BHS!$Z$31=$D10,CONCATENATE(BHS!$Y$31,"-"),""),IF(BHS!$Z$32=$D10,CONCATENATE(BHS!$Y$32,"-"),"")) | L10: =CONCATENATE(IF(BHS!$AH$13=$D10,CONCATENATE(BHS!$AG$13,"-"),""),IF(BHS!$AH$14=$D10,CONCATENATE(BHS!$AG$14,"-"),""),IF(BHS!$AH$15=$D10,CONCATENATE(BHS!$AG$15,"-"),""),IF(BHS!$AH$16=$D10,CONCATENATE(BHS!$AG$16,"-"),""),IF(BHS!$AH$17=$D10,CONCATENATE(BHS!$AG$17,"-"),""),IF(BHS!$AH$18=$D10,CONCATENATE(BHS!$AG$18,"-"),""),IF(BHS!$AH$19=$D10,CONCATENATE(BHS!$AG$19,"-"),""),IF(BHS!$AH$20=$D10,CONCATENATE(BHS!$AG$20,"-"),""),IF(BHS!$AH$21=$D10,CONCATENATE(BHS!$AG$21,"-"),""),IF(BHS!$AH$22=$D10,CONCATENATE(BHS!$AG$22,"-"),""),"") | M10: =CONCATENATE(IF(BHS!$AH$23=$D10,CONCATENATE(BHS!$AG$23,"-"),""),IF(BHS!$AH$24=$D10,CONCATENATE(BHS!$AG$24,"-"),""),IF(BHS!$AH$25=$D10,CONCATENATE(BHS!$AG$25,"-"),""),IF(BHS!$AH$26=$D10,CONCATENATE(BHS!$AG$26,"-"),""),IF(BHS!$AH$27=$D10,CONCATENATE(BHS!$AG$27,"-"),""),IF(BHS!$AH$28=$D10,CONCATENATE(BHS!$AG$28,"-"),""),IF(BHS!$AH$29=$D10,CONCATENATE(BHS!$AG$29,"-"),""),IF(BHS!$AH$30=$D10,CONCATENATE(BHS!$AG$30,"-"),""),IF(BHS!$AH$31=$D10,CONCATENATE(BHS!$AG$31,"-"),""),IF(BHS!$AH$32=$D10,CONCATENATE(BHS!$AG$32,"-"),"")) | N10: =CONCATENATE(F10,G10,H10,I10,J10,K10,L10,M10) | O10: 8 | P10: =IF(ISERROR(VLOOKUP($O10,$A$1:$B$100,2,FALSE)),"",VLOOKUP($O10,$A$1:$B$100,2,FALSE)) | Q10: =IF(P10="","",VLOOKUP($O10,$A$1:$E$100,5,FALSE)) | R10: =IF(P10="","",CHOOSE(VLOOKUP($O10,$A$1:$C$100,3,FALSE),AHS!$M$1,BHS!$M$1,CHS!$M$1,HMJHS!$M$1,KHS!$M$1,Kings!$M$1,MHS!$M$1,SWHS!$M$1,AMHS!$M$1,'S10'!$M$1,'S11'!$M$1,'S12'!$M$1,'S13'!$M$1,'S14'!$M$1,'S15'!$M$1,'S16'!$M$1,'S17'!$M$1,'S18'!$M$1,'S19'!$M$1,'S20'!$M$1)) | S10: =IF(P10="","",VLOOKUP($O10,$A$1:$E$100,4,FALSE)) | T10: =IF(P10="","",VLOOKUP($O10,$A$1:$N$100,14,FALSE))
A11: =IF(B11="","",COUNTIF($B$1:B10,B11)+B11) -> 1 | B11: =IF(E11="","",RANK(E11,$E$1:$E$100)) -> 1 | C11: 3 | D11: 1 | E11: =IF(CHS!$C$4="","",CHS!$C$4) -> 53.5 | F11: =CONCATENATE(IF(CHS!$J$13=$D11,CONCATENATE(CHS!$I$13,"-"),""),IF(CHS!$J$14=$D11,CONCATENATE(CHS!$I$14,"-"),""),IF(CHS!$J$15=$D11,CONCATENATE(CHS!$I$15,"-"),""),IF(CHS!$J$16=$D11,CONCATENATE(CHS!$I$16,"-"),""),IF(CHS!$J$17=$D11,CONCATENATE(CHS!$I$17,"-"),""),IF(CHS!$J$18=$D11,CONCATENATE(CHS!$I$18,"-"),""),IF(CHS!$J$19=$D11,CONCATENATE(CHS!$I$19,"-"),""),IF(CHS!$J$20=$D11,CONCATENATE(CHS!$I$20,"-"),""),IF(CHS!$J$21=$D11,CONCATENATE(CHS!$I$21,"-"),""),IF(CHS!$J$22=$D11,CONCATENATE(CHS!$I$22,"-"),""),) -> Jacob Hopkins-Nathan Kim- | G11: =CONCATENATE(IF(CHS!$J$23=$D11,CONCATENATE(CHS!$I$23,"-"),""),IF(CHS!$J$24=$D11,CONCATENATE(CHS!$I$24,"-"),""),IF(CHS!$J$25=$D11,CONCATENATE(CHS!$I$25,"-"),""),IF(CHS!$J$26=$D11,CONCATENATE(CHS!$I$26,"-"),""),IF(CHS!$J$27=$D11,CONCATENATE(CHS!$I$27,"-"),""),IF(CHS!$J$28=$D11,CONCATENATE(CHS!$I$28,"-"),""),IF(CHS!$J$29=$D11,CONCATENATE(CHS!$I$29,"-"),""),IF(CHS!$J$30=$D11,CONCATENATE(CHS!$I$30,"-"),""),IF(CHS!$J$31=$D11,CONCATENATE(CHS!$I$31,"-"),""),IF(CHS!$J$32=$D11,CONCATENATE(CHS!$I$32,"-"),"")) | H11: =CONCATENATE(IF(CHS!$R$13=$D11,CONCATENATE(CHS!$Q$13,"-"),""),IF(CHS!$R$14=$D11,CONCATENATE(CHS!$Q$14,"-"),""),IF(CHS!$R$15=$D11,CONCATENATE(CHS!$Q$15,"-"),""),IF(CHS!$R$16=$D11,CONCATENATE(CHS!$Q$16,"-"),""),IF(CHS!$R$17=$D11,CONCATENATE(CHS!$Q$17,"-"),""),IF(CHS!$R$18=$D11,CONCATENATE(CHS!$Q$18,"-"),""),IF(CHS!$R$19=$D11,CONCATENATE(CHS!$Q$19,"-"),""),IF(CHS!$R$20=$D11,CONCATENATE(CHS!$Q$20,"-"),""),IF(CHS!$R$21=$D11,CONCATENATE(CHS!$Q$21,"-"),""),IF(CHS!$R$22=$D11,CONCATENATE(CHS!$Q$22,"-"),"")) | I11: =CONCATENATE(,IF(CHS!$R$23=$D11,CONCATENATE(CHS!$Q$23,"-"),""),IF(CHS!$R$24=$D11,CONCATENATE(CHS!$Q$24,"-"),""),IF(CHS!$R$25=$D11,CONCATENATE(CHS!$Q$25,"-"),""),IF(CHS!$R$26=$D11,CONCATENATE(CHS!$Q$26,"-"),""),IF(CHS!$R$27=$D11,CONCATENATE(CHS!$Q$27,"-"),""),IF(CHS!$R$28=$D11,CONCATENATE(CHS!$Q$28,"-"),""),IF(CHS!$R$29=$D11,CONCATENATE(CHS!$Q$29,"-"),""),IF(CHS!$R$30=$D11,CONCATENATE(CHS!$Q$30,"-"),""),IF(CHS!$R$31=$D11,CONCATENATE(CHS!$Q$31,"-"),""),IF(CHS!$R$32=$D11,CONCATENATE(CHS!$Q$32,"-"),"")) | J11: =CONCATENATE(IF(CHS!$Z$13=$D11,CONCATENATE(CHS!$Y$13,"-"),""),IF(CHS!$Z$14=$D11,CONCATENATE(CHS!$Y$14,"-"),""),IF(CHS!$Z$15=$D11,CONCATENATE(CHS!$Y$15,"-"),""),IF(CHS!$Z$16=$D11,CONCATENATE(CHS!$Y$16,"-"),""),IF(CHS!$Z$17=$D11,CONCATENATE(CHS!$Y$17,"-"),""),IF(CHS!$Z$18=$D11,CONCATENATE(CHS!$Y$18,"-"),""),IF(CHS!$Z$19=$D11,CONCATENATE(CHS!$Y$19,"-"),""),IF(CHS!$Z$20=$D11,CONCATENATE(CHS!$Y$20,"-"),""),IF(CHS!$Z$21=$D11,CONCATENATE(CHS!$Y$21,"-"),""),IF(CHS!$Z$22=$D11,CONCATENATE(CHS!$Y$22,"-"),""),"") | K11: =CONCATENATE(IF(CHS!$Z$23=$D11,CONCATENATE(CHS!$Y$23,"-"),""),IF(CHS!$Z$24=$D11,CONCATENATE(CHS!$Y$24,"-"),""),IF(CHS!$Z$25=$D11,CONCATENATE(CHS!$Y$25,"-"),""),IF(CHS!$Z$26=$D11,CONCATENATE(CHS!$Y$26,"-"),""),IF(CHS!$Z$27=$D11,CONCATENATE(CHS!$Y$27,"-"),""),IF(CHS!$Z$28=$D11,CONCATENATE(CHS!$Y$28,"-"),""),IF(CHS!$Z$29=$D11,CONCATENATE(CHS!$Y$29,"-"),""),IF(CHS!$Z$30=$D11,CONCATENATE(CHS!$Y$30,"-"),""),IF(CHS!$Z$31=$D11,CONCATENATE(CHS!$Y$31,"-"),""),IF(CHS!$Z$32=$D11,CONCATENATE(CHS!$Y$32,"-"),"")) | L11: =CONCATENATE(IF(CHS!$AH$13=$D11,CONCATENATE(CHS!$AG$13,"-"),""),IF(CHS!$AH$14=$D11,CONCATENATE(CHS!$AG$14,"-"),""),IF(CHS!$AH$15=$D11,CONCATENATE(CHS!$AG$15,"-"),""),IF(CHS!$AH$16=$D11,CONCATENATE(CHS!$AG$16,"-"),""),IF(CHS!$AH$17=$D11,CONCATENATE(CHS!$AG$17,"-"),""),IF(CHS!$AH$18=$D11,CONCATENATE(CHS!$AG$18,"-"),""),IF(CHS!$AH$19=$D11,CONCATENATE(CHS!$AG$19,"-"),""),IF(CHS!$AH$20=$D11,CONCATENATE(CHS!$AG$20,"-"),""),IF(CHS!$AH$21=$D11,CONCATENATE(CHS!$AG$21,"-"),""),IF(CHS!$AH$22=$D11,CONCATENATE(CHS!$AG$22,"-"),""),"") | M11: =CONCATENATE(IF(CHS!$AH$23=$D11,CONCATENATE(CHS!$AG$23,"-"),""),IF(CHS!$AH$24=$D11,CONCATENATE(CHS!$AG$24,"-"),""),IF(CHS!$AH$25=$D11,CONCATENATE(CHS!$AG$25,"-"),""),IF(CHS!$AH$26=$D11,CONCATENATE(CHS!$AG$26,"-"),""),IF(CHS!$AH$27=$D11,CONCATENATE(CHS!$AG$27,"-"),""),IF(CHS!$AH$28=$D11,CONCATENATE(CHS!$AG$28,"-"),""),IF(CHS!$AH$29=$D11,CONCATENATE(CHS!$AG$29,"-"),""),IF(CHS!$AH$30=$D11,CONCATENATE(CHS!$AG$30,"-"),""),IF(CHS!$AH$31=$D11,CONCATENATE(CHS!$AG$31,"-"),""),IF(CHS!$AH$32=$D11,CONCATENATE(CHS!$AG$32,"-"),"")) | N11: =CONCATENATE(F11,G11,H11,I11,J11,K11,L11,M11) -> Jacob Hopkins-Nathan Kim- | O11: 9 | P11: =IF(ISERROR(VLOOKUP($O11,$A$1:$B$100,2,FALSE)),"",VLOOKUP($O11,$A$1:$B$100,2,FALSE)) | Q11: =IF(P11="","",VLOOKUP($O11,$A$1:$E$100,5,FALSE)) | R11: =IF(P11="","",CHOOSE(VLOOKUP($O11,$A$1:$C$100,3,FALSE),AHS!$M$1,BHS!$M$1,CHS!$M$1,HMJHS!$M$1,KHS!$M$1,Kings!$M$1,MHS!$M$1,SWHS!$M$1,AMHS!$M$1,'S10'!$M$1,'S11'!$M$1,'S12'!$M$1,'S13'!$M$1,'S14'!$M$1,'S15'!$M$1,'S16'!$M$1,'S17'!$M$1,'S18'!$M$1,'S19'!$M$1,'S20'!$M$1)) | S11: =IF(P11="","",VLOOKUP($O11,$A$1:$E$100,4,FALSE)) | T11: =IF(P11="","",VLOOKUP($O11,$A$1:$N$100,14,FALSE))
A12: =IF(B12="","",COUNTIF($B$1:B11,B12)+B12) | B12: =IF(E12="","",RANK(E12,$E$1:$E$100)) | C12: 3 | D12: 2 | E12: =IF(CHS!$C$5="","",CHS!$C$5) | F12: =CONCATENATE(IF(CHS!$J$13=$D12,CONCATENATE(CHS!$I$13,"-"),""),IF(CHS!$J$14=$D12,CONCATENATE(CHS!$I$14,"-"),""),IF(CHS!$J$15=$D12,CONCATENATE(CHS!$I$15,"-"),""),IF(CHS!$J$16=$D12,CONCATENATE(CHS!$I$16,"-"),""),IF(CHS!$J$17=$D12,CONCATENATE(CHS!$I$17,"-"),""),IF(CHS!$J$18=$D12,CONCATENATE(CHS!$I$18,"-"),""),IF(CHS!$J$19=$D12,CONCATENATE(CHS!$I$19,"-"),""),IF(CHS!$J$20=$D12,CONCATENATE(CHS!$I$20,"-"),""),IF(CHS!$J$21=$D12,CONCATENATE(CHS!$I$21,"-"),""),IF(CHS!$J$22=$D12,CONCATENATE(CHS!$I$22,"-"),""),) | G12: =CONCATENATE(IF(CHS!$J$23=$D12,CONCATENATE(CHS!$I$23,"-"),""),IF(CHS!$J$24=$D12,CONCATENATE(CHS!$I$24,"-"),""),IF(CHS!$J$25=$D12,CONCATENATE(CHS!$I$25,"-"),""),IF(CHS!$J$26=$D12,CONCATENATE(CHS!$I$26,"-"),""),IF(CHS!$J$27=$D12,CONCATENATE(CHS!$I$27,"-"),""),IF(CHS!$J$28=$D12,CONCATENATE(CHS!$I$28,"-"),""),IF(CHS!$J$29=$D12,CONCATENATE(CHS!$I$29,"-"),""),IF(CHS!$J$30=$D12,CONCATENATE(CHS!$I$30,"-"),""),IF(CHS!$J$31=$D12,CONCATENATE(CHS!$I$31,"-"),""),IF(CHS!$J$32=$D12,CONCATENATE(CHS!$I$32,"-"),"")) | H12: =CONCATENATE(IF(CHS!$R$13=$D12,CONCATENATE(CHS!$Q$13,"-"),""),IF(CHS!$R$14=$D12,CONCATENATE(CHS!$Q$14,"-"),""),IF(CHS!$R$15=$D12,CONCATENATE(CHS!$Q$15,"-"),""),IF(CHS!$R$16=$D12,CONCATENATE(CHS!$Q$16,"-"),""),IF(CHS!$R$17=$D12,CONCATENATE(CHS!$Q$17,"-"),""),IF(CHS!$R$18=$D12,CONCATENATE(CHS!$Q$18,"-"),""),IF(CHS!$R$19=$D12,CONCATENATE(CHS!$Q$19,"-"),""),IF(CHS!$R$20=$D12,CONCATENATE(CHS!$Q$20,"-"),""),IF(CHS!$R$21=$D12,CONCATENATE(CHS!$Q$21,"-"),""),IF(CHS!$R$22=$D12,CONCATENATE(CHS!$Q$22,"-"),"")) | I12: =CONCATENATE(,IF(CHS!$R$23=$D12,CONCATENATE(CHS!$Q$23,"-"),""),IF(CHS!$R$24=$D12,CONCATENATE(CHS!$Q$24,"-"),""),IF(CHS!$R$25=$D12,CONCATENATE(CHS!$Q$25,"-"),""),IF(CHS!$R$26=$D12,CONCATENATE(CHS!$Q$26,"-"),""),IF(CHS!$R$27=$D12,CONCATENATE(CHS!$Q$27,"-"),""),IF(CHS!$R$28=$D12,CONCATENATE(CHS!$Q$28,"-"),""),IF(CHS!$R$29=$D12,CONCATENATE(CHS!$Q$29,"-"),""),IF(CHS!$R$30=$D12,CONCATENATE(CHS!$Q$30,"-"),""),IF(CHS!$R$31=$D12,CONCATENATE(CHS!$Q$31,"-"),""),IF(CHS!$R$32=$D12,CONCATENATE(CHS!$Q$32,"-"),"")) | J12: =CONCATENATE(IF(CHS!$Z$13=$D12,CONCATENATE(CHS!$Y$13,"-"),""),IF(CHS!$Z$14=$D12,CONCATENATE(CHS!$Y$14,"-"),""),IF(CHS!$Z$15=$D12,CONCATENATE(CHS!$Y$15,"-"),""),IF(CHS!$Z$16=$D12,CONCATENATE(CHS!$Y$16,"-"),""),IF(CHS!$Z$17=$D12,CONCATENATE(CHS!$Y$17,"-"),""),IF(CHS!$Z$18=$D12,CONCATENATE(CHS!$Y$18,"-"),""),IF(CHS!$Z$19=$D12,CONCATENATE(CHS!$Y$19,"-"),""),IF(CHS!$Z$20=$D12,CONCATENATE(CHS!$Y$20,"-"),""),IF(CHS!$Z$21=$D12,CONCATENATE(CHS!$Y$21,"-"),""),IF(CHS!$Z$22=$D12,CONCATENATE(CHS!$Y$22,"-"),""),"") | K12: =CONCATENATE(IF(CHS!$Z$23=$D12,CONCATENATE(CHS!$Y$23,"-"),""),IF(CHS!$Z$24=$D12,CONCATENATE(CHS!$Y$24,"-"),""),IF(CHS!$Z$25=$D12,CONCATENATE(CHS!$Y$25,"-"),""),IF(CHS!$Z$26=$D12,CONCATENATE(CHS!$Y$26,"-"),""),IF(CHS!$Z$27=$D12,CONCATENATE(CHS!$Y$27,"-"),""),IF(CHS!$Z$28=$D12,CONCATENATE(CHS!$Y$28,"-"),""),IF(CHS!$Z$29=$D12,CONCATENATE(CHS!$Y$29,"-"),""),IF(CHS!$Z$30=$D12,CONCATENATE(CHS!$Y$30,"-"),""),IF(CHS!$Z$31=$D12,CONCATENATE(CHS!$Y$31,"-"),""),IF(CHS!$Z$32=$D12,CONCATENATE(CHS!$Y$32,"-"),"")) | L12: =CONCATENATE(IF(CHS!$AH$13=$D12,CONCATENATE(CHS!$AG$13,"-"),""),IF(CHS!$AH$14=$D12,CONCATENATE(CHS!$AG$14,"-"),""),IF(CHS!$AH$15=$D12,CONCATENATE(CHS!$AG$15,"-"),""),IF(CHS!$AH$16=$D12,CONCATENATE(CHS!$AG$16,"-"),""),IF(CHS!$AH$17=$D12,CONCATENATE(CHS!$AG$17,"-"),""),IF(CHS!$AH$18=$D12,CONCATENATE(CHS!$AG$18,"-"),""),IF(CHS!$AH$19=$D12,CONCATENATE(CHS!$AG$19,"-"),""),IF(CHS!$AH$20=$D12,CONCATENATE(CHS!$AG$20,"-"),""),IF(CHS!$AH$21=$D12,CONCATENATE(CHS!$AG$21,"-"),""),IF(CHS!$AH$22=$D12,CONCATENATE(CHS!$AG$22,"-"),""),"") | M12: =CONCATENATE(IF(CHS!$AH$23=$D12,CONCATENATE(CHS!$AG$23,"-"),""),IF(CHS!$AH$24=$D12,CONCATENATE(CHS!$AG$24,"-"),""),IF(CHS!$AH$25=$D12,CONCATENATE(CHS!$AG$25,"-"),""),IF(CHS!$AH$26=$D12,CONCATENATE(CHS!$AG$26,"-"),""),IF(CHS!$AH$27=$D12,CONCATENATE(CHS!$AG$27,"-"),""),IF(CHS!$AH$28=$D12,CONCATENATE(CHS!$AG$28,"-"),""),IF(CHS!$AH$29=$D12,CONCATENATE(CHS!$AG$29,"-"),""),IF(CHS!$AH$30=$D12,CONCATENATE(CHS!$AG$30,"-"),""),IF(CHS!$AH$31=$D12,CONCATENATE(CHS!$AG$31,"-"),""),IF(CHS!$AH$32=$D12,CONCATENATE(CHS!$AG$32,"-"),"")) | N12: =CONCATENATE(F12,G12,H12,I12,J12,K12,L12,M12) | O12: 10 | P12: =IF(ISERROR(VLOOKUP($O12,$A$1:$B$100,2,FALSE)),"",VLOOKUP($O12,$A$1:$B$100,2,FALSE)) | Q12: =IF(P12="","",VLOOKUP($O12,$A$1:$E$100,5,FALSE)) | R12: =IF(P12="","",CHOOSE(VLOOKUP($O12,$A$1:$C$100,3,FALSE),AHS!$M$1,BHS!$M$1,CHS!$M$1,HMJHS!$M$1,KHS!$M$1,Kings!$M$1,MHS!$M$1,SWHS!$M$1,AMHS!$M$1,'S10'!$M$1,'S11'!$M$1,'S12'!$M$1,'S13'!$M$1,'S14'!$M$1,'S15'!$M$1,'S16'!$M$1,'S17'!$M$1,'S18'!$M$1,'S19'!$M$1,'S20'!$M$1)) | S12: =IF(P12="","",VLOOKUP($O12,$A$1:$E$100,4,FALSE)) | T12: =IF(P12="","",VLOOKUP($O12,$A$1:$N$100,14,FALSE))
